2025-03-11 01:54:20,300 INFO    Thread-6  :40965 [wandb_setup.py:_flush():67] Current SDK version is 0.19.8
2025-03-11 01:54:20,301 INFO    Thread-6  :40965 [wandb_setup.py:_flush():67] Configure stats pid to 40965
2025-03-11 01:54:20,301 INFO    Thread-6  :40965 [wandb_setup.py:_flush():67] Loading settings from /Users/rudra_sarkar/.config/wandb/settings
2025-03-11 01:54:20,301 INFO    Thread-6  :40965 [wandb_setup.py:_flush():67] Loading settings from /Users/rudra_sarkar/Documents/PhD IIT Madras/Intro to Deep Learning M Khapra DA6401/DA6401 Assignment/da6401_assignment1/wandb/settings
2025-03-11 01:54:20,301 INFO    Thread-6  :40965 [wandb_setup.py:_flush():67] Loading settings from environment variables
2025-03-11 01:54:20,301 INFO    Thread-6  :40965 [wandb_init.py:setup_run_log_directory():647] Logging user logs to /Users/rudra_sarkar/Documents/PhD IIT Madras/Intro to Deep Learning M Khapra DA6401/DA6401 Assignment/da6401_assignment1/wandb/run-20250311_015420-n1t8npd4/logs/debug.log
2025-03-11 01:54:20,301 INFO    Thread-6  :40965 [wandb_init.py:setup_run_log_directory():648] Logging internal logs to /Users/rudra_sarkar/Documents/PhD IIT Madras/Intro to Deep Learning M Khapra DA6401/DA6401 Assignment/da6401_assignment1/wandb/run-20250311_015420-n1t8npd4/logs/debug-internal.log
2025-03-11 01:54:20,301 INFO    Thread-6  :40965 [wandb_init.py:init():761] calling init triggers
2025-03-11 01:54:20,301 INFO    Thread-6  :40965 [wandb_init.py:init():766] wandb.init called with sweep_config: {'activation': 'sigmoid', 'batch_size': 1024, 'beta1': 0.8869185313683007, 'beta2': 0.9063433377360736, 'epochs': 400, 'hidden_size': [1024, 512, 256], 'learning_rate': 0.0004317431813708533, 'loss': 'cross_entropy', 'momentum': 0.6467576653979039, 'optimizer': 'vanilla', 'weight_decay': 0.0006416305612402874, 'weight_init': 'xavier'}
config: {'epochs': 500, 'batch_size': 256, 'loss': 'mean_squared_error', 'optimizer': 'rmsprop', 'learning_rate': 0.007099906909450224, 'weight_init': 'random', 'hidden_size': [784, 10], 'num_layers': 2, 'input_size': 784, 'output_size': 10, 'beta': 0.5, 'activation': 'sigmoid', 'weight_decay': 0.0008742440920396431, 'beta1': 0.8414234168390405, 'beta2': 0.9680038847907864, 'epsilon': 1e-06, 'momentum': 0.8337275207438168, 'wandb_entity': 'da24d008-iit-madras', 'wandb_project': 'da24d008-assignment1', 'wandb_sweep': True, 'sweep_id': 'da24d008-assignment1/942fddeq', '_wandb': {}}
2025-03-11 01:54:20,301 INFO    Thread-6  :40965 [wandb_init.py:init():784] starting backend
2025-03-11 01:54:20,301 INFO    Thread-6  :40965 [wandb_init.py:init():788] sending inform_init request
2025-03-11 01:54:20,309 INFO    Thread-6  :40965 [backend.py:_multiprocessing_setup():101] multiprocessing start_methods=spawn,fork,forkserver, using: spawn
2025-03-11 01:54:20,309 INFO    Thread-6  :40965 [wandb_init.py:init():798] backend started and connected
2025-03-11 01:54:20,312 INFO    Thread-6  :40965 [wandb_run.py:_config_callback():1261] config_cb None None {'activation': 'sigmoid', 'batch_size': 1024, 'beta1': 0.8869185313683007, 'beta2': 0.9063433377360736, 'epochs': 400, 'hidden_size': [1024, 512, 256], 'learning_rate': 0.0004317431813708533, 'loss': 'cross_entropy', 'momentum': 0.6467576653979039, 'optimizer': 'vanilla', 'weight_decay': 0.0006416305612402874, 'weight_init': 'xavier'}
2025-03-11 01:54:20,409 INFO    Thread-6  :40965 [wandb_init.py:init():891] updated telemetry
2025-03-11 01:54:20,459 INFO    Thread-6  :40965 [wandb_init.py:init():915] communicating run to backend with 90.0 second timeout
2025-03-11 01:54:21,053 INFO    Thread-6  :40965 [wandb_init.py:init():990] starting run threads in backend
2025-03-11 01:54:21,274 INFO    Thread-6  :40965 [wandb_run.py:_console_start():2375] atexit reg
2025-03-11 01:54:21,274 INFO    Thread-6  :40965 [wandb_run.py:_redirect():2227] redirect: wrap_raw
2025-03-11 01:54:21,275 INFO    Thread-6  :40965 [wandb_run.py:_redirect():2292] Wrapping output streams.
2025-03-11 01:54:21,275 INFO    Thread-6  :40965 [wandb_run.py:_redirect():2315] Redirects installed.
2025-03-11 01:54:21,277 INFO    Thread-6  :40965 [wandb_init.py:init():1032] run started, returning control to user process
2025-03-11 01:54:47,545 INFO    Thread-6  :40965 [wandb_run.py:_config_callback():1261] config_cb ('_wandb', 'visualize', 'Confusion matrix') {'panel_type': 'Vega2', 'panel_config': {'panelDefId': 'wandb/confusion_matrix/v1', 'fieldSettings': {'Actual': 'Actual', 'Predicted': 'Predicted', 'nPredictions': 'nPredictions'}, 'stringSettings': {'title': 'Confusion Matrix Curve'}, 'transform': {'name': 'tableWithLeafColNames'}, 'userQuery': {'queryFields': [{'name': 'runSets', 'args': [{'name': 'runSets', 'value': '${runSets}'}], 'fields': [{'name': 'id', 'fields': []}, {'name': 'name', 'fields': []}, {'name': '_defaultColorIndex', 'fields': []}, {'name': 'summaryTable', 'args': [{'name': 'tableKey', 'value': 'Confusion matrix_table'}], 'fields': []}]}]}}} None
2025-03-11 01:55:56,098 INFO    Thread-6  :40965 [wandb_run.py:_config_callback():1261] config_cb ('_wandb', 'visualize', 'Confusion matrix') {'panel_type': 'Vega2', 'panel_config': {'panelDefId': 'wandb/confusion_matrix/v1', 'fieldSettings': {'Actual': 'Actual', 'Predicted': 'Predicted', 'nPredictions': 'nPredictions'}, 'stringSettings': {'title': 'Confusion Matrix Curve'}, 'transform': {'name': 'tableWithLeafColNames'}, 'userQuery': {'queryFields': [{'name': 'runSets', 'args': [{'name': 'runSets', 'value': '${runSets}'}], 'fields': [{'name': 'id', 'fields': []}, {'name': 'name', 'fields': []}, {'name': '_defaultColorIndex', 'fields': []}, {'name': 'summaryTable', 'args': [{'name': 'tableKey', 'value': 'Confusion matrix_table'}], 'fields': []}]}]}}} None
2025-03-11 02:12:55,901 INFO    Thread-6  :40965 [wandb_run.py:_config_callback():1261] config_cb ('_wandb', 'visualize', 'Confusion matrix') {'panel_type': 'Vega2', 'panel_config': {'panelDefId': 'wandb/confusion_matrix/v1', 'fieldSettings': {'Actual': 'Actual', 'Predicted': 'Predicted', 'nPredictions': 'nPredictions'}, 'stringSettings': {'title': 'Confusion Matrix Curve'}, 'transform': {'name': 'tableWithLeafColNames'}, 'userQuery': {'queryFields': [{'name': 'runSets', 'args': [{'name': 'runSets', 'value': '${runSets}'}], 'fields': [{'name': 'id', 'fields': []}, {'name': 'name', 'fields': []}, {'name': '_defaultColorIndex', 'fields': []}, {'name': 'summaryTable', 'args': [{'name': 'tableKey', 'value': 'Confusion matrix_table'}], 'fields': []}]}]}}} None
2025-03-11 02:31:38,031 INFO    Thread-6  :40965 [wandb_run.py:_config_callback():1261] config_cb ('_wandb', 'visualize', 'Confusion matrix') {'panel_type': 'Vega2', 'panel_config': {'panelDefId': 'wandb/confusion_matrix/v1', 'fieldSettings': {'Actual': 'Actual', 'Predicted': 'Predicted', 'nPredictions': 'nPredictions'}, 'stringSettings': {'title': 'Confusion Matrix Curve'}, 'transform': {'name': 'tableWithLeafColNames'}, 'userQuery': {'queryFields': [{'name': 'runSets', 'args': [{'name': 'runSets', 'value': '${runSets}'}], 'fields': [{'name': 'id', 'fields': []}, {'name': 'name', 'fields': []}, {'name': '_defaultColorIndex', 'fields': []}, {'name': 'summaryTable', 'args': [{'name': 'tableKey', 'value': 'Confusion matrix_table'}], 'fields': []}]}]}}} None
2025-03-11 02:48:08,198 INFO    Thread-6  :40965 [wandb_run.py:_config_callback():1261] config_cb ('_wandb', 'visualize', 'Confusion matrix') {'panel_type': 'Vega2', 'panel_config': {'panelDefId': 'wandb/confusion_matrix/v1', 'fieldSettings': {'Actual': 'Actual', 'Predicted': 'Predicted', 'nPredictions': 'nPredictions'}, 'stringSettings': {'title': 'Confusion Matrix Curve'}, 'transform': {'name': 'tableWithLeafColNames'}, 'userQuery': {'queryFields': [{'name': 'runSets', 'args': [{'name': 'runSets', 'value': '${runSets}'}], 'fields': [{'name': 'id', 'fields': []}, {'name': 'name', 'fields': []}, {'name': '_defaultColorIndex', 'fields': []}, {'name': 'summaryTable', 'args': [{'name': 'tableKey', 'value': 'Confusion matrix_table'}], 'fields': []}]}]}}} None
2025-03-11 03:04:01,959 INFO    Thread-6  :40965 [wandb_run.py:_config_callback():1261] config_cb ('_wandb', 'visualize', 'Confusion matrix') {'panel_type': 'Vega2', 'panel_config': {'panelDefId': 'wandb/confusion_matrix/v1', 'fieldSettings': {'Actual': 'Actual', 'Predicted': 'Predicted', 'nPredictions': 'nPredictions'}, 'stringSettings': {'title': 'Confusion Matrix Curve'}, 'transform': {'name': 'tableWithLeafColNames'}, 'userQuery': {'queryFields': [{'name': 'runSets', 'args': [{'name': 'runSets', 'value': '${runSets}'}], 'fields': [{'name': 'id', 'fields': []}, {'name': 'name', 'fields': []}, {'name': '_defaultColorIndex', 'fields': []}, {'name': 'summaryTable', 'args': [{'name': 'tableKey', 'value': 'Confusion matrix_table'}], 'fields': []}]}]}}} None
2025-03-11 03:04:30,124 INFO    Thread-6  :40965 [wandb_run.py:_config_callback():1261] config_cb ('_wandb', 'visualize', 'Confusion matrix') {'panel_type': 'Vega2', 'panel_config': {'panelDefId': 'wandb/confusion_matrix/v1', 'fieldSettings': {'Actual': 'Actual', 'Predicted': 'Predicted', 'nPredictions': 'nPredictions'}, 'stringSettings': {'title': 'Confusion Matrix Curve'}, 'transform': {'name': 'tableWithLeafColNames'}, 'userQuery': {'queryFields': [{'name': 'runSets', 'args': [{'name': 'runSets', 'value': '${runSets}'}], 'fields': [{'name': 'id', 'fields': []}, {'name': 'name', 'fields': []}, {'name': '_defaultColorIndex', 'fields': []}, {'name': 'summaryTable', 'args': [{'name': 'tableKey', 'value': 'Confusion matrix_table'}], 'fields': []}]}]}}} None
2025-03-11 03:05:34,438 INFO    Thread-6  :40965 [wandb_run.py:_config_callback():1261] config_cb ('_wandb', 'visualize', 'Confusion matrix') {'panel_type': 'Vega2', 'panel_config': {'panelDefId': 'wandb/confusion_matrix/v1', 'fieldSettings': {'Actual': 'Actual', 'Predicted': 'Predicted', 'nPredictions': 'nPredictions'}, 'stringSettings': {'title': 'Confusion Matrix Curve'}, 'transform': {'name': 'tableWithLeafColNames'}, 'userQuery': {'queryFields': [{'name': 'runSets', 'args': [{'name': 'runSets', 'value': '${runSets}'}], 'fields': [{'name': 'id', 'fields': []}, {'name': 'name', 'fields': []}, {'name': '_defaultColorIndex', 'fields': []}, {'name': 'summaryTable', 'args': [{'name': 'tableKey', 'value': 'Confusion matrix_table'}], 'fields': []}]}]}}} None
2025-03-11 03:28:42,469 INFO    Thread-2  :40965 [retry.py:__call__():175] Retry attempt failed:
Traceback (most recent call last):
  File "/Users/rudra_sarkar/Documents/CNN_practice/5h_prac/TFODCourse/tfod_new/env/lib/python3.8/site-packages/urllib3/connection.py", line 174, in _new_conn
    conn = connection.create_connection(
  File "/Users/rudra_sarkar/Documents/CNN_practice/5h_prac/TFODCourse/tfod_new/env/lib/python3.8/site-packages/urllib3/util/connection.py", line 72, in create_connection
    for res in socket.getaddrinfo(host, port, family, socket.SOCK_STREAM):
  File "/Users/rudra_sarkar/Documents/CNN_practice/5h_prac/TFODCourse/tfod_new/env/lib/python3.8/socket.py", line 918, in getaddrinfo
    for res in _socket.getaddrinfo(host, port, family, type, proto, flags):
socket.gaierror: [Errno 8] nodename nor servname provided, or not known

During handling of the above exception, another exception occurred:

Traceback (most recent call last):
  File "/Users/rudra_sarkar/Documents/CNN_practice/5h_prac/TFODCourse/tfod_new/env/lib/python3.8/site-packages/urllib3/connectionpool.py", line 703, in urlopen
    httplib_response = self._make_request(
  File "/Users/rudra_sarkar/Documents/CNN_practice/5h_prac/TFODCourse/tfod_new/env/lib/python3.8/site-packages/urllib3/connectionpool.py", line 386, in _make_request
    self._validate_conn(conn)
  File "/Users/rudra_sarkar/Documents/CNN_practice/5h_prac/TFODCourse/tfod_new/env/lib/python3.8/site-packages/urllib3/connectionpool.py", line 1042, in _validate_conn
    conn.connect()
  File "/Users/rudra_sarkar/Documents/CNN_practice/5h_prac/TFODCourse/tfod_new/env/lib/python3.8/site-packages/urllib3/connection.py", line 358, in connect
    self.sock = conn = self._new_conn()
  File "/Users/rudra_sarkar/Documents/CNN_practice/5h_prac/TFODCourse/tfod_new/env/lib/python3.8/site-packages/urllib3/connection.py", line 186, in _new_conn
    raise NewConnectionError(
urllib3.exceptions.NewConnectionError: <urllib3.connection.HTTPSConnection object at 0x16c687970>: Failed to establish a new connection: [Errno 8] nodename nor servname provided, or not known

During handling of the above exception, another exception occurred:

Traceback (most recent call last):
  File "/Users/rudra_sarkar/Documents/CNN_practice/5h_prac/TFODCourse/tfod_new/env/lib/python3.8/site-packages/requests/adapters.py", line 489, in send
    resp = conn.urlopen(
  File "/Users/rudra_sarkar/Documents/CNN_practice/5h_prac/TFODCourse/tfod_new/env/lib/python3.8/site-packages/urllib3/connectionpool.py", line 787, in urlopen
    retries = retries.increment(
  File "/Users/rudra_sarkar/Documents/CNN_practice/5h_prac/TFODCourse/tfod_new/env/lib/python3.8/site-packages/urllib3/util/retry.py", line 592, in increment
    raise MaxRetryError(_pool, url, error or ResponseError(cause))
urllib3.exceptions.MaxRetryError: HTTPSConnectionPool(host='api.wandb.ai', port=443): Max retries exceeded with url: /graphql (Caused by NewConnectionError('<urllib3.connection.HTTPSConnection object at 0x16c687970>: Failed to establish a new connection: [Errno 8] nodename nor servname provided, or not known'))

During handling of the above exception, another exception occurred:

Traceback (most recent call last):
  File "/Users/rudra_sarkar/Documents/CNN_practice/5h_prac/TFODCourse/tfod_new/env/lib/python3.8/site-packages/wandb/sdk/lib/retry.py", line 134, in __call__
    result = self._call_fn(*args, **kwargs)
  File "/Users/rudra_sarkar/Documents/CNN_practice/5h_prac/TFODCourse/tfod_new/env/lib/python3.8/site-packages/wandb/sdk/internal/internal_api.py", line 398, in execute
    return self.client.execute(*args, **kwargs)  # type: ignore
  File "/Users/rudra_sarkar/Documents/CNN_practice/5h_prac/TFODCourse/tfod_new/env/lib/python3.8/site-packages/wandb/vendor/gql-0.2.0/wandb_gql/client.py", line 52, in execute
    result = self._get_result(document, *args, **kwargs)
  File "/Users/rudra_sarkar/Documents/CNN_practice/5h_prac/TFODCourse/tfod_new/env/lib/python3.8/site-packages/wandb/vendor/gql-0.2.0/wandb_gql/client.py", line 60, in _get_result
    return self.transport.execute(document, *args, **kwargs)
  File "/Users/rudra_sarkar/Documents/CNN_practice/5h_prac/TFODCourse/tfod_new/env/lib/python3.8/site-packages/wandb/sdk/lib/gql_request.py", line 58, in execute
    request = self.session.post(self.url, **post_args)
  File "/Users/rudra_sarkar/Documents/CNN_practice/5h_prac/TFODCourse/tfod_new/env/lib/python3.8/site-packages/requests/sessions.py", line 635, in post
    return self.request("POST", url, data=data, json=json, **kwargs)
  File "/Users/rudra_sarkar/Documents/CNN_practice/5h_prac/TFODCourse/tfod_new/env/lib/python3.8/site-packages/requests/sessions.py", line 587, in request
    resp = self.send(prep, **send_kwargs)
  File "/Users/rudra_sarkar/Documents/CNN_practice/5h_prac/TFODCourse/tfod_new/env/lib/python3.8/site-packages/requests/sessions.py", line 701, in send
    r = adapter.send(request, **kwargs)
  File "/Users/rudra_sarkar/Documents/CNN_practice/5h_prac/TFODCourse/tfod_new/env/lib/python3.8/site-packages/requests/adapters.py", line 565, in send
    raise ConnectionError(e, request=request)
requests.exceptions.ConnectionError: HTTPSConnectionPool(host='api.wandb.ai', port=443): Max retries exceeded with url: /graphql (Caused by NewConnectionError('<urllib3.connection.HTTPSConnection object at 0x16c687970>: Failed to establish a new connection: [Errno 8] nodename nor servname provided, or not known'))
2025-03-11 04:36:00,621 INFO    Thread-6  :40965 [wandb_run.py:_config_callback():1261] config_cb ('_wandb', 'visualize', 'Confusion matrix') {'panel_type': 'Vega2', 'panel_config': {'panelDefId': 'wandb/confusion_matrix/v1', 'fieldSettings': {'Actual': 'Actual', 'Predicted': 'Predicted', 'nPredictions': 'nPredictions'}, 'stringSettings': {'title': 'Confusion Matrix Curve'}, 'transform': {'name': 'tableWithLeafColNames'}, 'userQuery': {'queryFields': [{'name': 'runSets', 'args': [{'name': 'runSets', 'value': '${runSets}'}], 'fields': [{'name': 'id', 'fields': []}, {'name': 'name', 'fields': []}, {'name': '_defaultColorIndex', 'fields': []}, {'name': 'summaryTable', 'args': [{'name': 'tableKey', 'value': 'Confusion matrix_table'}], 'fields': []}]}]}}} None
2025-03-11 04:53:18,556 INFO    Thread-6  :40965 [retry.py:__call__():175] Retry attempt failed:
Traceback (most recent call last):
  File "/Users/rudra_sarkar/Documents/CNN_practice/5h_prac/TFODCourse/tfod_new/env/lib/python3.8/site-packages/urllib3/connection.py", line 174, in _new_conn
    conn = connection.create_connection(
  File "/Users/rudra_sarkar/Documents/CNN_practice/5h_prac/TFODCourse/tfod_new/env/lib/python3.8/site-packages/urllib3/util/connection.py", line 72, in create_connection
    for res in socket.getaddrinfo(host, port, family, socket.SOCK_STREAM):
  File "/Users/rudra_sarkar/Documents/CNN_practice/5h_prac/TFODCourse/tfod_new/env/lib/python3.8/socket.py", line 918, in getaddrinfo
    for res in _socket.getaddrinfo(host, port, family, type, proto, flags):
socket.gaierror: [Errno 8] nodename nor servname provided, or not known

During handling of the above exception, another exception occurred:

Traceback (most recent call last):
  File "/Users/rudra_sarkar/Documents/CNN_practice/5h_prac/TFODCourse/tfod_new/env/lib/python3.8/site-packages/urllib3/connectionpool.py", line 703, in urlopen
    httplib_response = self._make_request(
  File "/Users/rudra_sarkar/Documents/CNN_practice/5h_prac/TFODCourse/tfod_new/env/lib/python3.8/site-packages/urllib3/connectionpool.py", line 386, in _make_request
    self._validate_conn(conn)
  File "/Users/rudra_sarkar/Documents/CNN_practice/5h_prac/TFODCourse/tfod_new/env/lib/python3.8/site-packages/urllib3/connectionpool.py", line 1042, in _validate_conn
    conn.connect()
  File "/Users/rudra_sarkar/Documents/CNN_practice/5h_prac/TFODCourse/tfod_new/env/lib/python3.8/site-packages/urllib3/connection.py", line 358, in connect
    self.sock = conn = self._new_conn()
  File "/Users/rudra_sarkar/Documents/CNN_practice/5h_prac/TFODCourse/tfod_new/env/lib/python3.8/site-packages/urllib3/connection.py", line 186, in _new_conn
    raise NewConnectionError(
urllib3.exceptions.NewConnectionError: <urllib3.connection.HTTPSConnection object at 0x1683ba0d0>: Failed to establish a new connection: [Errno 8] nodename nor servname provided, or not known

During handling of the above exception, another exception occurred:

Traceback (most recent call last):
  File "/Users/rudra_sarkar/Documents/CNN_practice/5h_prac/TFODCourse/tfod_new/env/lib/python3.8/site-packages/requests/adapters.py", line 489, in send
    resp = conn.urlopen(
  File "/Users/rudra_sarkar/Documents/CNN_practice/5h_prac/TFODCourse/tfod_new/env/lib/python3.8/site-packages/urllib3/connectionpool.py", line 787, in urlopen
    retries = retries.increment(
  File "/Users/rudra_sarkar/Documents/CNN_practice/5h_prac/TFODCourse/tfod_new/env/lib/python3.8/site-packages/urllib3/util/retry.py", line 592, in increment
    raise MaxRetryError(_pool, url, error or ResponseError(cause))
urllib3.exceptions.MaxRetryError: HTTPSConnectionPool(host='api.wandb.ai', port=443): Max retries exceeded with url: /graphql (Caused by NewConnectionError('<urllib3.connection.HTTPSConnection object at 0x1683ba0d0>: Failed to establish a new connection: [Errno 8] nodename nor servname provided, or not known'))

During handling of the above exception, another exception occurred:

Traceback (most recent call last):
  File "/Users/rudra_sarkar/Documents/CNN_practice/5h_prac/TFODCourse/tfod_new/env/lib/python3.8/site-packages/wandb/sdk/lib/retry.py", line 134, in __call__
    result = self._call_fn(*args, **kwargs)
  File "/Users/rudra_sarkar/Documents/CNN_practice/5h_prac/TFODCourse/tfod_new/env/lib/python3.8/site-packages/wandb/apis/public/api.py", line 79, in execute
    return self._client.execute(*args, **kwargs)
  File "/Users/rudra_sarkar/Documents/CNN_practice/5h_prac/TFODCourse/tfod_new/env/lib/python3.8/site-packages/wandb/vendor/gql-0.2.0/wandb_gql/client.py", line 52, in execute
    result = self._get_result(document, *args, **kwargs)
  File "/Users/rudra_sarkar/Documents/CNN_practice/5h_prac/TFODCourse/tfod_new/env/lib/python3.8/site-packages/wandb/vendor/gql-0.2.0/wandb_gql/client.py", line 60, in _get_result
    return self.transport.execute(document, *args, **kwargs)
  File "/Users/rudra_sarkar/Documents/CNN_practice/5h_prac/TFODCourse/tfod_new/env/lib/python3.8/site-packages/wandb/sdk/lib/gql_request.py", line 58, in execute
    request = self.session.post(self.url, **post_args)
  File "/Users/rudra_sarkar/Documents/CNN_practice/5h_prac/TFODCourse/tfod_new/env/lib/python3.8/site-packages/requests/sessions.py", line 635, in post
    return self.request("POST", url, data=data, json=json, **kwargs)
  File "/Users/rudra_sarkar/Documents/CNN_practice/5h_prac/TFODCourse/tfod_new/env/lib/python3.8/site-packages/requests/sessions.py", line 587, in request
    resp = self.send(prep, **send_kwargs)
  File "/Users/rudra_sarkar/Documents/CNN_practice/5h_prac/TFODCourse/tfod_new/env/lib/python3.8/site-packages/requests/sessions.py", line 701, in send
    r = adapter.send(request, **kwargs)
  File "/Users/rudra_sarkar/Documents/CNN_practice/5h_prac/TFODCourse/tfod_new/env/lib/python3.8/site-packages/requests/adapters.py", line 565, in send
    raise ConnectionError(e, request=request)
requests.exceptions.ConnectionError: HTTPSConnectionPool(host='api.wandb.ai', port=443): Max retries exceeded with url: /graphql (Caused by NewConnectionError('<urllib3.connection.HTTPSConnection object at 0x1683ba0d0>: Failed to establish a new connection: [Errno 8] nodename nor servname provided, or not known'))
2025-03-11 05:12:38,824 INFO    Thread-6  :40965 [wandb_run.py:_config_callback():1261] config_cb ('_wandb', 'visualize', 'Confusion matrix') {'panel_type': 'Vega2', 'panel_config': {'panelDefId': 'wandb/confusion_matrix/v1', 'fieldSettings': {'Actual': 'Actual', 'Predicted': 'Predicted', 'nPredictions': 'nPredictions'}, 'stringSettings': {'title': 'Confusion Matrix Curve'}, 'transform': {'name': 'tableWithLeafColNames'}, 'userQuery': {'queryFields': [{'name': 'runSets', 'args': [{'name': 'runSets', 'value': '${runSets}'}], 'fields': [{'name': 'id', 'fields': []}, {'name': 'name', 'fields': []}, {'name': '_defaultColorIndex', 'fields': []}, {'name': 'summaryTable', 'args': [{'name': 'tableKey', 'value': 'Confusion matrix_table'}], 'fields': []}]}]}}} None
2025-03-11 05:12:42,197 INFO    Thread-6  :40965 [retry.py:__call__():175] Retry attempt failed:
Traceback (most recent call last):
  File "/Users/rudra_sarkar/Documents/CNN_practice/5h_prac/TFODCourse/tfod_new/env/lib/python3.8/site-packages/urllib3/connection.py", line 174, in _new_conn
    conn = connection.create_connection(
  File "/Users/rudra_sarkar/Documents/CNN_practice/5h_prac/TFODCourse/tfod_new/env/lib/python3.8/site-packages/urllib3/util/connection.py", line 72, in create_connection
    for res in socket.getaddrinfo(host, port, family, socket.SOCK_STREAM):
  File "/Users/rudra_sarkar/Documents/CNN_practice/5h_prac/TFODCourse/tfod_new/env/lib/python3.8/socket.py", line 918, in getaddrinfo
    for res in _socket.getaddrinfo(host, port, family, type, proto, flags):
socket.gaierror: [Errno 8] nodename nor servname provided, or not known

During handling of the above exception, another exception occurred:

Traceback (most recent call last):
  File "/Users/rudra_sarkar/Documents/CNN_practice/5h_prac/TFODCourse/tfod_new/env/lib/python3.8/site-packages/urllib3/connectionpool.py", line 703, in urlopen
    httplib_response = self._make_request(
  File "/Users/rudra_sarkar/Documents/CNN_practice/5h_prac/TFODCourse/tfod_new/env/lib/python3.8/site-packages/urllib3/connectionpool.py", line 386, in _make_request
    self._validate_conn(conn)
  File "/Users/rudra_sarkar/Documents/CNN_practice/5h_prac/TFODCourse/tfod_new/env/lib/python3.8/site-packages/urllib3/connectionpool.py", line 1042, in _validate_conn
    conn.connect()
  File "/Users/rudra_sarkar/Documents/CNN_practice/5h_prac/TFODCourse/tfod_new/env/lib/python3.8/site-packages/urllib3/connection.py", line 358, in connect
    self.sock = conn = self._new_conn()
  File "/Users/rudra_sarkar/Documents/CNN_practice/5h_prac/TFODCourse/tfod_new/env/lib/python3.8/site-packages/urllib3/connection.py", line 186, in _new_conn
    raise NewConnectionError(
urllib3.exceptions.NewConnectionError: <urllib3.connection.HTTPSConnection object at 0x1681c14c0>: Failed to establish a new connection: [Errno 8] nodename nor servname provided, or not known

During handling of the above exception, another exception occurred:

Traceback (most recent call last):
  File "/Users/rudra_sarkar/Documents/CNN_practice/5h_prac/TFODCourse/tfod_new/env/lib/python3.8/site-packages/requests/adapters.py", line 489, in send
    resp = conn.urlopen(
  File "/Users/rudra_sarkar/Documents/CNN_practice/5h_prac/TFODCourse/tfod_new/env/lib/python3.8/site-packages/urllib3/connectionpool.py", line 787, in urlopen
    retries = retries.increment(
  File "/Users/rudra_sarkar/Documents/CNN_practice/5h_prac/TFODCourse/tfod_new/env/lib/python3.8/site-packages/urllib3/util/retry.py", line 592, in increment
    raise MaxRetryError(_pool, url, error or ResponseError(cause))
urllib3.exceptions.MaxRetryError: HTTPSConnectionPool(host='api.wandb.ai', port=443): Max retries exceeded with url: /graphql (Caused by NewConnectionError('<urllib3.connection.HTTPSConnection object at 0x1681c14c0>: Failed to establish a new connection: [Errno 8] nodename nor servname provided, or not known'))

During handling of the above exception, another exception occurred:

Traceback (most recent call last):
  File "/Users/rudra_sarkar/Documents/CNN_practice/5h_prac/TFODCourse/tfod_new/env/lib/python3.8/site-packages/wandb/sdk/lib/retry.py", line 134, in __call__
    result = self._call_fn(*args, **kwargs)
  File "/Users/rudra_sarkar/Documents/CNN_practice/5h_prac/TFODCourse/tfod_new/env/lib/python3.8/site-packages/wandb/apis/public/api.py", line 79, in execute
    return self._client.execute(*args, **kwargs)
  File "/Users/rudra_sarkar/Documents/CNN_practice/5h_prac/TFODCourse/tfod_new/env/lib/python3.8/site-packages/wandb/vendor/gql-0.2.0/wandb_gql/client.py", line 52, in execute
    result = self._get_result(document, *args, **kwargs)
  File "/Users/rudra_sarkar/Documents/CNN_practice/5h_prac/TFODCourse/tfod_new/env/lib/python3.8/site-packages/wandb/vendor/gql-0.2.0/wandb_gql/client.py", line 60, in _get_result
    return self.transport.execute(document, *args, **kwargs)
  File "/Users/rudra_sarkar/Documents/CNN_practice/5h_prac/TFODCourse/tfod_new/env/lib/python3.8/site-packages/wandb/sdk/lib/gql_request.py", line 58, in execute
    request = self.session.post(self.url, **post_args)
  File "/Users/rudra_sarkar/Documents/CNN_practice/5h_prac/TFODCourse/tfod_new/env/lib/python3.8/site-packages/requests/sessions.py", line 635, in post
    return self.request("POST", url, data=data, json=json, **kwargs)
  File "/Users/rudra_sarkar/Documents/CNN_practice/5h_prac/TFODCourse/tfod_new/env/lib/python3.8/site-packages/requests/sessions.py", line 587, in request
    resp = self.send(prep, **send_kwargs)
  File "/Users/rudra_sarkar/Documents/CNN_practice/5h_prac/TFODCourse/tfod_new/env/lib/python3.8/site-packages/requests/sessions.py", line 701, in send
    r = adapter.send(request, **kwargs)
  File "/Users/rudra_sarkar/Documents/CNN_practice/5h_prac/TFODCourse/tfod_new/env/lib/python3.8/site-packages/requests/adapters.py", line 565, in send
    raise ConnectionError(e, request=request)
requests.exceptions.ConnectionError: HTTPSConnectionPool(host='api.wandb.ai', port=443): Max retries exceeded with url: /graphql (Caused by NewConnectionError('<urllib3.connection.HTTPSConnection object at 0x1681c14c0>: Failed to establish a new connection: [Errno 8] nodename nor servname provided, or not known'))
2025-03-11 07:29:45,219 INFO    Thread-6  :40965 [wandb_run.py:_config_callback():1261] config_cb ('_wandb', 'visualize', 'Confusion matrix') {'panel_type': 'Vega2', 'panel_config': {'panelDefId': 'wandb/confusion_matrix/v1', 'fieldSettings': {'Actual': 'Actual', 'Predicted': 'Predicted', 'nPredictions': 'nPredictions'}, 'stringSettings': {'title': 'Confusion Matrix Curve'}, 'transform': {'name': 'tableWithLeafColNames'}, 'userQuery': {'queryFields': [{'name': 'runSets', 'args': [{'name': 'runSets', 'value': '${runSets}'}], 'fields': [{'name': 'id', 'fields': []}, {'name': 'name', 'fields': []}, {'name': '_defaultColorIndex', 'fields': []}, {'name': 'summaryTable', 'args': [{'name': 'tableKey', 'value': 'Confusion matrix_table'}], 'fields': []}]}]}}} None
2025-03-11 09:06:00,702 INFO    Thread-6  :40965 [wandb_run.py:_config_callback():1261] config_cb ('_wandb', 'visualize', 'Confusion matrix') {'panel_type': 'Vega2', 'panel_config': {'panelDefId': 'wandb/confusion_matrix/v1', 'fieldSettings': {'Actual': 'Actual', 'Predicted': 'Predicted', 'nPredictions': 'nPredictions'}, 'stringSettings': {'title': 'Confusion Matrix Curve'}, 'transform': {'name': 'tableWithLeafColNames'}, 'userQuery': {'queryFields': [{'name': 'runSets', 'args': [{'name': 'runSets', 'value': '${runSets}'}], 'fields': [{'name': 'id', 'fields': []}, {'name': 'name', 'fields': []}, {'name': '_defaultColorIndex', 'fields': []}, {'name': 'summaryTable', 'args': [{'name': 'tableKey', 'value': 'Confusion matrix_table'}], 'fields': []}]}]}}} None
2025-03-11 09:06:56,447 INFO    Thread-6  :40965 [wandb_run.py:_config_callback():1261] config_cb ('_wandb', 'visualize', 'Confusion matrix') {'panel_type': 'Vega2', 'panel_config': {'panelDefId': 'wandb/confusion_matrix/v1', 'fieldSettings': {'Actual': 'Actual', 'Predicted': 'Predicted', 'nPredictions': 'nPredictions'}, 'stringSettings': {'title': 'Confusion Matrix Curve'}, 'transform': {'name': 'tableWithLeafColNames'}, 'userQuery': {'queryFields': [{'name': 'runSets', 'args': [{'name': 'runSets', 'value': '${runSets}'}], 'fields': [{'name': 'id', 'fields': []}, {'name': 'name', 'fields': []}, {'name': '_defaultColorIndex', 'fields': []}, {'name': 'summaryTable', 'args': [{'name': 'tableKey', 'value': 'Confusion matrix_table'}], 'fields': []}]}]}}} None
2025-03-11 09:07:12,612 INFO    MainThread:40965 [wandb_run.py:_config_callback():1261] config_cb None None {'sweep_name': 'epochs-400_batch_size-1024_loss-cross_entropy_optimizer-vanilla_learning_rate-0.0004317431813708533_weight_init-xavier_hidden_size-[1024, 512, 256]_num_layers-2_beta-0.5_activation-sigmoid_weight_decay-0.0006416305612402874_beta1-0.8869185313683007_beta2-0.9063433377360736_epsilon-1e-06_momentum-0.6467576653979039_wandb_sweep-True_sweep_id-da24d008-assignment1/942fddeq'}
2025-03-11 09:07:12,615 INFO    MainThread:40965 [wandb_run.py:_finish():2112] finishing run da24d008-iit-madras/da24d008-assignment1/n1t8npd4
2025-03-11 09:07:12,616 INFO    MainThread:40965 [wandb_run.py:_atexit_cleanup():2340] got exitcode: 0
2025-03-11 09:07:12,617 INFO    MainThread:40965 [wandb_run.py:_restore():2322] restore
2025-03-11 09:07:12,618 INFO    MainThread:40965 [wandb_run.py:_restore():2328] restore done
2025-03-11 09:07:12,619 INFO    Thread-6  :40965 [wandb_run.py:_finish():2112] finishing run da24d008-iit-madras/da24d008-assignment1/n1t8npd4
