2025-03-16 14:29:14,322 INFO    Thread-10 :47473 [wandb_setup.py:_flush():67] Current SDK version is 0.19.8
2025-03-16 14:29:14,322 INFO    Thread-10 :47473 [wandb_setup.py:_flush():67] Configure stats pid to 47473
2025-03-16 14:29:14,322 INFO    Thread-10 :47473 [wandb_setup.py:_flush():67] Loading settings from /Users/rudra_sarkar/.config/wandb/settings
2025-03-16 14:29:14,322 INFO    Thread-10 :47473 [wandb_setup.py:_flush():67] Loading settings from /Users/rudra_sarkar/Documents/PhD IIT Madras/Intro to Deep Learning M Khapra DA6401/DA6401 Assignment/da6401_assignment1/wandb/settings
2025-03-16 14:29:14,322 INFO    Thread-10 :47473 [wandb_setup.py:_flush():67] Loading settings from environment variables
2025-03-16 14:29:14,323 INFO    Thread-10 :47473 [wandb_init.py:setup_run_log_directory():647] Logging user logs to /Users/rudra_sarkar/Documents/PhD IIT Madras/Intro to Deep Learning M Khapra DA6401/DA6401 Assignment/da6401_assignment1/wandb/run-20250316_142914-endsj1id/logs/debug.log
2025-03-16 14:29:14,323 INFO    Thread-10 :47473 [wandb_init.py:setup_run_log_directory():648] Logging internal logs to /Users/rudra_sarkar/Documents/PhD IIT Madras/Intro to Deep Learning M Khapra DA6401/DA6401 Assignment/da6401_assignment1/wandb/run-20250316_142914-endsj1id/logs/debug-internal.log
2025-03-16 14:29:14,323 INFO    Thread-10 :47473 [wandb_init.py:init():761] calling init triggers
2025-03-16 14:29:14,323 INFO    Thread-10 :47473 [wandb_init.py:init():766] wandb.init called with sweep_config: {'activation': 'tanh', 'batch_size': 512, 'beta1': 0.8711250590310524, 'beta2': 0.9251582917881293, 'epochs': 800, 'hidden_size': [32, 64, 128], 'learning_rate': 0.06037295182858165, 'loss': 'cross_entropy', 'momentum': 0.5598717811457493, 'optimizer': 'momentum', 'weight_decay': 0.0004973268194687681, 'weight_init': 'xavier'}
config: {'epochs': 1000, 'batch_size': 2048, 'loss': 'mean_squared_error', 'optimizer': 'nag', 'learning_rate': 0.00026285156241413375, 'weight_init': 'random', 'hidden_size': [32, 64, 128], 'num_layers': 3, 'input_size': 784, 'output_size': 10, 'beta': 0.5, 'activation': 'sigmoid', 'weight_decay': 0.00048039147181433553, 'beta1': 0.9118309630208516, 'beta2': 0.9705103158013686, 'epsilon': 1e-06, 'momentum': 0.664240466251716, 'wandb_entity': 'da24d008-iit-madras', 'wandb_project': 'da24d008-assignment1', 'wandb_sweep': True, 'sweep_id': None, 'dataset': 'fashion_mnist', '_wandb': {}}
2025-03-16 14:29:14,323 INFO    Thread-10 :47473 [wandb_init.py:init():784] starting backend
2025-03-16 14:29:14,324 INFO    Thread-10 :47473 [wandb_init.py:init():788] sending inform_init request
2025-03-16 14:29:14,330 INFO    Thread-10 :47473 [backend.py:_multiprocessing_setup():101] multiprocessing start_methods=spawn,fork,forkserver, using: spawn
2025-03-16 14:29:14,330 INFO    Thread-10 :47473 [wandb_init.py:init():798] backend started and connected
2025-03-16 14:29:14,332 INFO    Thread-10 :47473 [wandb_run.py:_config_callback():1261] config_cb None None {'activation': 'tanh', 'batch_size': 512, 'beta1': 0.8711250590310524, 'beta2': 0.9251582917881293, 'epochs': 800, 'hidden_size': [32, 64, 128], 'learning_rate': 0.06037295182858165, 'loss': 'cross_entropy', 'momentum': 0.5598717811457493, 'optimizer': 'momentum', 'weight_decay': 0.0004973268194687681, 'weight_init': 'xavier'}
2025-03-16 14:29:14,344 INFO    Thread-10 :47473 [wandb_init.py:init():891] updated telemetry
2025-03-16 14:29:14,379 INFO    Thread-10 :47473 [wandb_init.py:init():915] communicating run to backend with 90.0 second timeout
2025-03-16 14:29:14,786 INFO    Thread-10 :47473 [wandb_init.py:init():990] starting run threads in backend
2025-03-16 14:29:14,955 INFO    Thread-10 :47473 [wandb_run.py:_console_start():2375] atexit reg
2025-03-16 14:29:14,956 INFO    Thread-10 :47473 [wandb_run.py:_redirect():2227] redirect: wrap_raw
2025-03-16 14:29:14,956 INFO    Thread-10 :47473 [wandb_run.py:_redirect():2292] Wrapping output streams.
2025-03-16 14:29:14,956 INFO    Thread-10 :47473 [wandb_run.py:_redirect():2315] Redirects installed.
2025-03-16 14:29:14,960 INFO    Thread-10 :47473 [wandb_init.py:init():1032] run started, returning control to user process
2025-03-16 14:29:19,592 INFO    Thread-10 :47473 [wandb_run.py:_config_callback():1261] config_cb ('_wandb', 'visualize', 'Confusion matrix') {'panel_type': 'Vega2', 'panel_config': {'panelDefId': 'wandb/confusion_matrix/v1', 'fieldSettings': {'Actual': 'Actual', 'Predicted': 'Predicted', 'nPredictions': 'nPredictions'}, 'stringSettings': {'title': 'Confusion Matrix Curve'}, 'transform': {'name': 'tableWithLeafColNames'}, 'userQuery': {'queryFields': [{'name': 'runSets', 'args': [{'name': 'runSets', 'value': '${runSets}'}], 'fields': [{'name': 'id', 'fields': []}, {'name': 'name', 'fields': []}, {'name': '_defaultColorIndex', 'fields': []}, {'name': 'summaryTable', 'args': [{'name': 'tableKey', 'value': 'Confusion matrix_table'}], 'fields': []}]}]}}} None
2025-03-16 14:29:38,498 INFO    Thread-10 :47473 [wandb_run.py:_config_callback():1261] config_cb ('_wandb', 'visualize', 'Confusion matrix') {'panel_type': 'Vega2', 'panel_config': {'panelDefId': 'wandb/confusion_matrix/v1', 'fieldSettings': {'Actual': 'Actual', 'Predicted': 'Predicted', 'nPredictions': 'nPredictions'}, 'stringSettings': {'title': 'Confusion Matrix Curve'}, 'transform': {'name': 'tableWithLeafColNames'}, 'userQuery': {'queryFields': [{'name': 'runSets', 'args': [{'name': 'runSets', 'value': '${runSets}'}], 'fields': [{'name': 'id', 'fields': []}, {'name': 'name', 'fields': []}, {'name': '_defaultColorIndex', 'fields': []}, {'name': 'summaryTable', 'args': [{'name': 'tableKey', 'value': 'Confusion matrix_table'}], 'fields': []}]}]}}} None
2025-03-16 14:30:00,876 INFO    Thread-10 :47473 [wandb_run.py:_config_callback():1261] config_cb ('_wandb', 'visualize', 'Confusion matrix') {'panel_type': 'Vega2', 'panel_config': {'panelDefId': 'wandb/confusion_matrix/v1', 'fieldSettings': {'Actual': 'Actual', 'Predicted': 'Predicted', 'nPredictions': 'nPredictions'}, 'stringSettings': {'title': 'Confusion Matrix Curve'}, 'transform': {'name': 'tableWithLeafColNames'}, 'userQuery': {'queryFields': [{'name': 'runSets', 'args': [{'name': 'runSets', 'value': '${runSets}'}], 'fields': [{'name': 'id', 'fields': []}, {'name': 'name', 'fields': []}, {'name': '_defaultColorIndex', 'fields': []}, {'name': 'summaryTable', 'args': [{'name': 'tableKey', 'value': 'Confusion matrix_table'}], 'fields': []}]}]}}} None
2025-03-16 14:30:27,955 INFO    Thread-10 :47473 [wandb_run.py:_config_callback():1261] config_cb ('_wandb', 'visualize', 'Confusion matrix') {'panel_type': 'Vega2', 'panel_config': {'panelDefId': 'wandb/confusion_matrix/v1', 'fieldSettings': {'Actual': 'Actual', 'Predicted': 'Predicted', 'nPredictions': 'nPredictions'}, 'stringSettings': {'title': 'Confusion Matrix Curve'}, 'transform': {'name': 'tableWithLeafColNames'}, 'userQuery': {'queryFields': [{'name': 'runSets', 'args': [{'name': 'runSets', 'value': '${runSets}'}], 'fields': [{'name': 'id', 'fields': []}, {'name': 'name', 'fields': []}, {'name': '_defaultColorIndex', 'fields': []}, {'name': 'summaryTable', 'args': [{'name': 'tableKey', 'value': 'Confusion matrix_table'}], 'fields': []}]}]}}} None
2025-03-16 14:30:53,210 INFO    Thread-10 :47473 [wandb_run.py:_config_callback():1261] config_cb ('_wandb', 'visualize', 'Confusion matrix') {'panel_type': 'Vega2', 'panel_config': {'panelDefId': 'wandb/confusion_matrix/v1', 'fieldSettings': {'Actual': 'Actual', 'Predicted': 'Predicted', 'nPredictions': 'nPredictions'}, 'stringSettings': {'title': 'Confusion Matrix Curve'}, 'transform': {'name': 'tableWithLeafColNames'}, 'userQuery': {'queryFields': [{'name': 'runSets', 'args': [{'name': 'runSets', 'value': '${runSets}'}], 'fields': [{'name': 'id', 'fields': []}, {'name': 'name', 'fields': []}, {'name': '_defaultColorIndex', 'fields': []}, {'name': 'summaryTable', 'args': [{'name': 'tableKey', 'value': 'Confusion matrix_table'}], 'fields': []}]}]}}} None
2025-03-16 14:31:16,322 INFO    Thread-10 :47473 [wandb_run.py:_config_callback():1261] config_cb ('_wandb', 'visualize', 'Confusion matrix') {'panel_type': 'Vega2', 'panel_config': {'panelDefId': 'wandb/confusion_matrix/v1', 'fieldSettings': {'Actual': 'Actual', 'Predicted': 'Predicted', 'nPredictions': 'nPredictions'}, 'stringSettings': {'title': 'Confusion Matrix Curve'}, 'transform': {'name': 'tableWithLeafColNames'}, 'userQuery': {'queryFields': [{'name': 'runSets', 'args': [{'name': 'runSets', 'value': '${runSets}'}], 'fields': [{'name': 'id', 'fields': []}, {'name': 'name', 'fields': []}, {'name': '_defaultColorIndex', 'fields': []}, {'name': 'summaryTable', 'args': [{'name': 'tableKey', 'value': 'Confusion matrix_table'}], 'fields': []}]}]}}} None
2025-03-16 14:47:32,452 INFO    Thread-10 :47473 [wandb_run.py:_config_callback():1261] config_cb ('_wandb', 'visualize', 'Confusion matrix') {'panel_type': 'Vega2', 'panel_config': {'panelDefId': 'wandb/confusion_matrix/v1', 'fieldSettings': {'Actual': 'Actual', 'Predicted': 'Predicted', 'nPredictions': 'nPredictions'}, 'stringSettings': {'title': 'Confusion Matrix Curve'}, 'transform': {'name': 'tableWithLeafColNames'}, 'userQuery': {'queryFields': [{'name': 'runSets', 'args': [{'name': 'runSets', 'value': '${runSets}'}], 'fields': [{'name': 'id', 'fields': []}, {'name': 'name', 'fields': []}, {'name': '_defaultColorIndex', 'fields': []}, {'name': 'summaryTable', 'args': [{'name': 'tableKey', 'value': 'Confusion matrix_table'}], 'fields': []}]}]}}} None
2025-03-16 15:04:07,892 INFO    Thread-10 :47473 [retry.py:__call__():175] Retry attempt failed:
Traceback (most recent call last):
  File "/Users/rudra_sarkar/Documents/CNN_practice/5h_prac/TFODCourse/tfod_new/env/lib/python3.8/site-packages/urllib3/connection.py", line 174, in _new_conn
    conn = connection.create_connection(
  File "/Users/rudra_sarkar/Documents/CNN_practice/5h_prac/TFODCourse/tfod_new/env/lib/python3.8/site-packages/urllib3/util/connection.py", line 72, in create_connection
    for res in socket.getaddrinfo(host, port, family, socket.SOCK_STREAM):
  File "/Users/rudra_sarkar/Documents/CNN_practice/5h_prac/TFODCourse/tfod_new/env/lib/python3.8/socket.py", line 918, in getaddrinfo
    for res in _socket.getaddrinfo(host, port, family, type, proto, flags):
socket.gaierror: [Errno 8] nodename nor servname provided, or not known

During handling of the above exception, another exception occurred:

Traceback (most recent call last):
  File "/Users/rudra_sarkar/Documents/CNN_practice/5h_prac/TFODCourse/tfod_new/env/lib/python3.8/site-packages/urllib3/connectionpool.py", line 703, in urlopen
    httplib_response = self._make_request(
  File "/Users/rudra_sarkar/Documents/CNN_practice/5h_prac/TFODCourse/tfod_new/env/lib/python3.8/site-packages/urllib3/connectionpool.py", line 386, in _make_request
    self._validate_conn(conn)
  File "/Users/rudra_sarkar/Documents/CNN_practice/5h_prac/TFODCourse/tfod_new/env/lib/python3.8/site-packages/urllib3/connectionpool.py", line 1042, in _validate_conn
    conn.connect()
  File "/Users/rudra_sarkar/Documents/CNN_practice/5h_prac/TFODCourse/tfod_new/env/lib/python3.8/site-packages/urllib3/connection.py", line 358, in connect
    self.sock = conn = self._new_conn()
  File "/Users/rudra_sarkar/Documents/CNN_practice/5h_prac/TFODCourse/tfod_new/env/lib/python3.8/site-packages/urllib3/connection.py", line 186, in _new_conn
    raise NewConnectionError(
urllib3.exceptions.NewConnectionError: <urllib3.connection.HTTPSConnection object at 0x1661b0f40>: Failed to establish a new connection: [Errno 8] nodename nor servname provided, or not known

During handling of the above exception, another exception occurred:

Traceback (most recent call last):
  File "/Users/rudra_sarkar/Documents/CNN_practice/5h_prac/TFODCourse/tfod_new/env/lib/python3.8/site-packages/requests/adapters.py", line 489, in send
    resp = conn.urlopen(
  File "/Users/rudra_sarkar/Documents/CNN_practice/5h_prac/TFODCourse/tfod_new/env/lib/python3.8/site-packages/urllib3/connectionpool.py", line 787, in urlopen
    retries = retries.increment(
  File "/Users/rudra_sarkar/Documents/CNN_practice/5h_prac/TFODCourse/tfod_new/env/lib/python3.8/site-packages/urllib3/util/retry.py", line 592, in increment
    raise MaxRetryError(_pool, url, error or ResponseError(cause))
urllib3.exceptions.MaxRetryError: HTTPSConnectionPool(host='api.wandb.ai', port=443): Max retries exceeded with url: /graphql (Caused by NewConnectionError('<urllib3.connection.HTTPSConnection object at 0x1661b0f40>: Failed to establish a new connection: [Errno 8] nodename nor servname provided, or not known'))

During handling of the above exception, another exception occurred:

Traceback (most recent call last):
  File "/Users/rudra_sarkar/Documents/CNN_practice/5h_prac/TFODCourse/tfod_new/env/lib/python3.8/site-packages/wandb/sdk/lib/retry.py", line 134, in __call__
    result = self._call_fn(*args, **kwargs)
  File "/Users/rudra_sarkar/Documents/CNN_practice/5h_prac/TFODCourse/tfod_new/env/lib/python3.8/site-packages/wandb/apis/public/api.py", line 79, in execute
    return self._client.execute(*args, **kwargs)
  File "/Users/rudra_sarkar/Documents/CNN_practice/5h_prac/TFODCourse/tfod_new/env/lib/python3.8/site-packages/wandb/vendor/gql-0.2.0/wandb_gql/client.py", line 52, in execute
    result = self._get_result(document, *args, **kwargs)
  File "/Users/rudra_sarkar/Documents/CNN_practice/5h_prac/TFODCourse/tfod_new/env/lib/python3.8/site-packages/wandb/vendor/gql-0.2.0/wandb_gql/client.py", line 60, in _get_result
    return self.transport.execute(document, *args, **kwargs)
  File "/Users/rudra_sarkar/Documents/CNN_practice/5h_prac/TFODCourse/tfod_new/env/lib/python3.8/site-packages/wandb/sdk/lib/gql_request.py", line 58, in execute
    request = self.session.post(self.url, **post_args)
  File "/Users/rudra_sarkar/Documents/CNN_practice/5h_prac/TFODCourse/tfod_new/env/lib/python3.8/site-packages/requests/sessions.py", line 635, in post
    return self.request("POST", url, data=data, json=json, **kwargs)
  File "/Users/rudra_sarkar/Documents/CNN_practice/5h_prac/TFODCourse/tfod_new/env/lib/python3.8/site-packages/requests/sessions.py", line 587, in request
    resp = self.send(prep, **send_kwargs)
  File "/Users/rudra_sarkar/Documents/CNN_practice/5h_prac/TFODCourse/tfod_new/env/lib/python3.8/site-packages/requests/sessions.py", line 701, in send
    r = adapter.send(request, **kwargs)
  File "/Users/rudra_sarkar/Documents/CNN_practice/5h_prac/TFODCourse/tfod_new/env/lib/python3.8/site-packages/requests/adapters.py", line 565, in send
    raise ConnectionError(e, request=request)
requests.exceptions.ConnectionError: HTTPSConnectionPool(host='api.wandb.ai', port=443): Max retries exceeded with url: /graphql (Caused by NewConnectionError('<urllib3.connection.HTTPSConnection object at 0x1661b0f40>: Failed to establish a new connection: [Errno 8] nodename nor servname provided, or not known'))
2025-03-16 15:04:09,730 INFO    Thread-3  :47473 [retry.py:__call__():175] Retry attempt failed:
Traceback (most recent call last):
  File "/Users/rudra_sarkar/Documents/CNN_practice/5h_prac/TFODCourse/tfod_new/env/lib/python3.8/site-packages/urllib3/connection.py", line 174, in _new_conn
    conn = connection.create_connection(
  File "/Users/rudra_sarkar/Documents/CNN_practice/5h_prac/TFODCourse/tfod_new/env/lib/python3.8/site-packages/urllib3/util/connection.py", line 72, in create_connection
    for res in socket.getaddrinfo(host, port, family, socket.SOCK_STREAM):
  File "/Users/rudra_sarkar/Documents/CNN_practice/5h_prac/TFODCourse/tfod_new/env/lib/python3.8/socket.py", line 918, in getaddrinfo
    for res in _socket.getaddrinfo(host, port, family, type, proto, flags):
socket.gaierror: [Errno 8] nodename nor servname provided, or not known

During handling of the above exception, another exception occurred:

Traceback (most recent call last):
  File "/Users/rudra_sarkar/Documents/CNN_practice/5h_prac/TFODCourse/tfod_new/env/lib/python3.8/site-packages/urllib3/connectionpool.py", line 703, in urlopen
    httplib_response = self._make_request(
  File "/Users/rudra_sarkar/Documents/CNN_practice/5h_prac/TFODCourse/tfod_new/env/lib/python3.8/site-packages/urllib3/connectionpool.py", line 386, in _make_request
    self._validate_conn(conn)
  File "/Users/rudra_sarkar/Documents/CNN_practice/5h_prac/TFODCourse/tfod_new/env/lib/python3.8/site-packages/urllib3/connectionpool.py", line 1042, in _validate_conn
    conn.connect()
  File "/Users/rudra_sarkar/Documents/CNN_practice/5h_prac/TFODCourse/tfod_new/env/lib/python3.8/site-packages/urllib3/connection.py", line 358, in connect
    self.sock = conn = self._new_conn()
  File "/Users/rudra_sarkar/Documents/CNN_practice/5h_prac/TFODCourse/tfod_new/env/lib/python3.8/site-packages/urllib3/connection.py", line 186, in _new_conn
    raise NewConnectionError(
urllib3.exceptions.NewConnectionError: <urllib3.connection.HTTPSConnection object at 0x1661b0a60>: Failed to establish a new connection: [Errno 8] nodename nor servname provided, or not known

During handling of the above exception, another exception occurred:

Traceback (most recent call last):
  File "/Users/rudra_sarkar/Documents/CNN_practice/5h_prac/TFODCourse/tfod_new/env/lib/python3.8/site-packages/requests/adapters.py", line 489, in send
    resp = conn.urlopen(
  File "/Users/rudra_sarkar/Documents/CNN_practice/5h_prac/TFODCourse/tfod_new/env/lib/python3.8/site-packages/urllib3/connectionpool.py", line 787, in urlopen
    retries = retries.increment(
  File "/Users/rudra_sarkar/Documents/CNN_practice/5h_prac/TFODCourse/tfod_new/env/lib/python3.8/site-packages/urllib3/util/retry.py", line 592, in increment
    raise MaxRetryError(_pool, url, error or ResponseError(cause))
urllib3.exceptions.MaxRetryError: HTTPSConnectionPool(host='api.wandb.ai', port=443): Max retries exceeded with url: /graphql (Caused by NewConnectionError('<urllib3.connection.HTTPSConnection object at 0x1661b0a60>: Failed to establish a new connection: [Errno 8] nodename nor servname provided, or not known'))

During handling of the above exception, another exception occurred:

Traceback (most recent call last):
  File "/Users/rudra_sarkar/Documents/CNN_practice/5h_prac/TFODCourse/tfod_new/env/lib/python3.8/site-packages/wandb/sdk/lib/retry.py", line 134, in __call__
    result = self._call_fn(*args, **kwargs)
  File "/Users/rudra_sarkar/Documents/CNN_practice/5h_prac/TFODCourse/tfod_new/env/lib/python3.8/site-packages/wandb/sdk/internal/internal_api.py", line 398, in execute
    return self.client.execute(*args, **kwargs)  # type: ignore
  File "/Users/rudra_sarkar/Documents/CNN_practice/5h_prac/TFODCourse/tfod_new/env/lib/python3.8/site-packages/wandb/vendor/gql-0.2.0/wandb_gql/client.py", line 52, in execute
    result = self._get_result(document, *args, **kwargs)
  File "/Users/rudra_sarkar/Documents/CNN_practice/5h_prac/TFODCourse/tfod_new/env/lib/python3.8/site-packages/wandb/vendor/gql-0.2.0/wandb_gql/client.py", line 60, in _get_result
    return self.transport.execute(document, *args, **kwargs)
  File "/Users/rudra_sarkar/Documents/CNN_practice/5h_prac/TFODCourse/tfod_new/env/lib/python3.8/site-packages/wandb/sdk/lib/gql_request.py", line 58, in execute
    request = self.session.post(self.url, **post_args)
  File "/Users/rudra_sarkar/Documents/CNN_practice/5h_prac/TFODCourse/tfod_new/env/lib/python3.8/site-packages/requests/sessions.py", line 635, in post
    return self.request("POST", url, data=data, json=json, **kwargs)
  File "/Users/rudra_sarkar/Documents/CNN_practice/5h_prac/TFODCourse/tfod_new/env/lib/python3.8/site-packages/requests/sessions.py", line 587, in request
    resp = self.send(prep, **send_kwargs)
  File "/Users/rudra_sarkar/Documents/CNN_practice/5h_prac/TFODCourse/tfod_new/env/lib/python3.8/site-packages/requests/sessions.py", line 701, in send
    r = adapter.send(request, **kwargs)
  File "/Users/rudra_sarkar/Documents/CNN_practice/5h_prac/TFODCourse/tfod_new/env/lib/python3.8/site-packages/requests/adapters.py", line 565, in send
    raise ConnectionError(e, request=request)
requests.exceptions.ConnectionError: HTTPSConnectionPool(host='api.wandb.ai', port=443): Max retries exceeded with url: /graphql (Caused by NewConnectionError('<urllib3.connection.HTTPSConnection object at 0x1661b0a60>: Failed to establish a new connection: [Errno 8] nodename nor servname provided, or not known'))
2025-03-16 15:21:16,902 INFO    Thread-10 :47473 [wandb_run.py:_config_callback():1261] config_cb ('_wandb', 'visualize', 'Confusion matrix') {'panel_type': 'Vega2', 'panel_config': {'panelDefId': 'wandb/confusion_matrix/v1', 'fieldSettings': {'Actual': 'Actual', 'Predicted': 'Predicted', 'nPredictions': 'nPredictions'}, 'stringSettings': {'title': 'Confusion Matrix Curve'}, 'transform': {'name': 'tableWithLeafColNames'}, 'userQuery': {'queryFields': [{'name': 'runSets', 'args': [{'name': 'runSets', 'value': '${runSets}'}], 'fields': [{'name': 'id', 'fields': []}, {'name': 'name', 'fields': []}, {'name': '_defaultColorIndex', 'fields': []}, {'name': 'summaryTable', 'args': [{'name': 'tableKey', 'value': 'Confusion matrix_table'}], 'fields': []}]}]}}} None
2025-03-16 15:38:31,860 INFO    Thread-10 :47473 [retry.py:__call__():175] Retry attempt failed:
Traceback (most recent call last):
  File "/Users/rudra_sarkar/Documents/CNN_practice/5h_prac/TFODCourse/tfod_new/env/lib/python3.8/site-packages/urllib3/connection.py", line 174, in _new_conn
    conn = connection.create_connection(
  File "/Users/rudra_sarkar/Documents/CNN_practice/5h_prac/TFODCourse/tfod_new/env/lib/python3.8/site-packages/urllib3/util/connection.py", line 72, in create_connection
    for res in socket.getaddrinfo(host, port, family, socket.SOCK_STREAM):
  File "/Users/rudra_sarkar/Documents/CNN_practice/5h_prac/TFODCourse/tfod_new/env/lib/python3.8/socket.py", line 918, in getaddrinfo
    for res in _socket.getaddrinfo(host, port, family, type, proto, flags):
socket.gaierror: [Errno 8] nodename nor servname provided, or not known

During handling of the above exception, another exception occurred:

Traceback (most recent call last):
  File "/Users/rudra_sarkar/Documents/CNN_practice/5h_prac/TFODCourse/tfod_new/env/lib/python3.8/site-packages/urllib3/connectionpool.py", line 703, in urlopen
    httplib_response = self._make_request(
  File "/Users/rudra_sarkar/Documents/CNN_practice/5h_prac/TFODCourse/tfod_new/env/lib/python3.8/site-packages/urllib3/connectionpool.py", line 386, in _make_request
    self._validate_conn(conn)
  File "/Users/rudra_sarkar/Documents/CNN_practice/5h_prac/TFODCourse/tfod_new/env/lib/python3.8/site-packages/urllib3/connectionpool.py", line 1042, in _validate_conn
    conn.connect()
  File "/Users/rudra_sarkar/Documents/CNN_practice/5h_prac/TFODCourse/tfod_new/env/lib/python3.8/site-packages/urllib3/connection.py", line 358, in connect
    self.sock = conn = self._new_conn()
  File "/Users/rudra_sarkar/Documents/CNN_practice/5h_prac/TFODCourse/tfod_new/env/lib/python3.8/site-packages/urllib3/connection.py", line 186, in _new_conn
    raise NewConnectionError(
urllib3.exceptions.NewConnectionError: <urllib3.connection.HTTPSConnection object at 0x15785b0d0>: Failed to establish a new connection: [Errno 8] nodename nor servname provided, or not known

During handling of the above exception, another exception occurred:

Traceback (most recent call last):
  File "/Users/rudra_sarkar/Documents/CNN_practice/5h_prac/TFODCourse/tfod_new/env/lib/python3.8/site-packages/requests/adapters.py", line 489, in send
    resp = conn.urlopen(
  File "/Users/rudra_sarkar/Documents/CNN_practice/5h_prac/TFODCourse/tfod_new/env/lib/python3.8/site-packages/urllib3/connectionpool.py", line 787, in urlopen
    retries = retries.increment(
  File "/Users/rudra_sarkar/Documents/CNN_practice/5h_prac/TFODCourse/tfod_new/env/lib/python3.8/site-packages/urllib3/util/retry.py", line 592, in increment
    raise MaxRetryError(_pool, url, error or ResponseError(cause))
urllib3.exceptions.MaxRetryError: HTTPSConnectionPool(host='api.wandb.ai', port=443): Max retries exceeded with url: /graphql (Caused by NewConnectionError('<urllib3.connection.HTTPSConnection object at 0x15785b0d0>: Failed to establish a new connection: [Errno 8] nodename nor servname provided, or not known'))

During handling of the above exception, another exception occurred:

Traceback (most recent call last):
  File "/Users/rudra_sarkar/Documents/CNN_practice/5h_prac/TFODCourse/tfod_new/env/lib/python3.8/site-packages/wandb/sdk/lib/retry.py", line 134, in __call__
    result = self._call_fn(*args, **kwargs)
  File "/Users/rudra_sarkar/Documents/CNN_practice/5h_prac/TFODCourse/tfod_new/env/lib/python3.8/site-packages/wandb/apis/public/api.py", line 79, in execute
    return self._client.execute(*args, **kwargs)
  File "/Users/rudra_sarkar/Documents/CNN_practice/5h_prac/TFODCourse/tfod_new/env/lib/python3.8/site-packages/wandb/vendor/gql-0.2.0/wandb_gql/client.py", line 52, in execute
    result = self._get_result(document, *args, **kwargs)
  File "/Users/rudra_sarkar/Documents/CNN_practice/5h_prac/TFODCourse/tfod_new/env/lib/python3.8/site-packages/wandb/vendor/gql-0.2.0/wandb_gql/client.py", line 60, in _get_result
    return self.transport.execute(document, *args, **kwargs)
  File "/Users/rudra_sarkar/Documents/CNN_practice/5h_prac/TFODCourse/tfod_new/env/lib/python3.8/site-packages/wandb/sdk/lib/gql_request.py", line 58, in execute
    request = self.session.post(self.url, **post_args)
  File "/Users/rudra_sarkar/Documents/CNN_practice/5h_prac/TFODCourse/tfod_new/env/lib/python3.8/site-packages/requests/sessions.py", line 635, in post
    return self.request("POST", url, data=data, json=json, **kwargs)
  File "/Users/rudra_sarkar/Documents/CNN_practice/5h_prac/TFODCourse/tfod_new/env/lib/python3.8/site-packages/requests/sessions.py", line 587, in request
    resp = self.send(prep, **send_kwargs)
  File "/Users/rudra_sarkar/Documents/CNN_practice/5h_prac/TFODCourse/tfod_new/env/lib/python3.8/site-packages/requests/sessions.py", line 701, in send
    r = adapter.send(request, **kwargs)
  File "/Users/rudra_sarkar/Documents/CNN_practice/5h_prac/TFODCourse/tfod_new/env/lib/python3.8/site-packages/requests/adapters.py", line 565, in send
    raise ConnectionError(e, request=request)
requests.exceptions.ConnectionError: HTTPSConnectionPool(host='api.wandb.ai', port=443): Max retries exceeded with url: /graphql (Caused by NewConnectionError('<urllib3.connection.HTTPSConnection object at 0x15785b0d0>: Failed to establish a new connection: [Errno 8] nodename nor servname provided, or not known'))
2025-03-16 16:02:01,686 INFO    Thread-10 :47473 [wandb_run.py:_config_callback():1261] config_cb ('_wandb', 'visualize', 'Confusion matrix') {'panel_type': 'Vega2', 'panel_config': {'panelDefId': 'wandb/confusion_matrix/v1', 'fieldSettings': {'Actual': 'Actual', 'Predicted': 'Predicted', 'nPredictions': 'nPredictions'}, 'stringSettings': {'title': 'Confusion Matrix Curve'}, 'transform': {'name': 'tableWithLeafColNames'}, 'userQuery': {'queryFields': [{'name': 'runSets', 'args': [{'name': 'runSets', 'value': '${runSets}'}], 'fields': [{'name': 'id', 'fields': []}, {'name': 'name', 'fields': []}, {'name': '_defaultColorIndex', 'fields': []}, {'name': 'summaryTable', 'args': [{'name': 'tableKey', 'value': 'Confusion matrix_table'}], 'fields': []}]}]}}} None
2025-03-16 16:18:53,441 INFO    Thread-10 :47473 [retry.py:__call__():175] Retry attempt failed:
Traceback (most recent call last):
  File "/Users/rudra_sarkar/Documents/CNN_practice/5h_prac/TFODCourse/tfod_new/env/lib/python3.8/site-packages/urllib3/connection.py", line 174, in _new_conn
    conn = connection.create_connection(
  File "/Users/rudra_sarkar/Documents/CNN_practice/5h_prac/TFODCourse/tfod_new/env/lib/python3.8/site-packages/urllib3/util/connection.py", line 72, in create_connection
    for res in socket.getaddrinfo(host, port, family, socket.SOCK_STREAM):
  File "/Users/rudra_sarkar/Documents/CNN_practice/5h_prac/TFODCourse/tfod_new/env/lib/python3.8/socket.py", line 918, in getaddrinfo
    for res in _socket.getaddrinfo(host, port, family, type, proto, flags):
socket.gaierror: [Errno 8] nodename nor servname provided, or not known

During handling of the above exception, another exception occurred:

Traceback (most recent call last):
  File "/Users/rudra_sarkar/Documents/CNN_practice/5h_prac/TFODCourse/tfod_new/env/lib/python3.8/site-packages/urllib3/connectionpool.py", line 703, in urlopen
    httplib_response = self._make_request(
  File "/Users/rudra_sarkar/Documents/CNN_practice/5h_prac/TFODCourse/tfod_new/env/lib/python3.8/site-packages/urllib3/connectionpool.py", line 386, in _make_request
    self._validate_conn(conn)
  File "/Users/rudra_sarkar/Documents/CNN_practice/5h_prac/TFODCourse/tfod_new/env/lib/python3.8/site-packages/urllib3/connectionpool.py", line 1042, in _validate_conn
    conn.connect()
  File "/Users/rudra_sarkar/Documents/CNN_practice/5h_prac/TFODCourse/tfod_new/env/lib/python3.8/site-packages/urllib3/connection.py", line 358, in connect
    self.sock = conn = self._new_conn()
  File "/Users/rudra_sarkar/Documents/CNN_practice/5h_prac/TFODCourse/tfod_new/env/lib/python3.8/site-packages/urllib3/connection.py", line 186, in _new_conn
    raise NewConnectionError(
urllib3.exceptions.NewConnectionError: <urllib3.connection.HTTPSConnection object at 0x1578ed5e0>: Failed to establish a new connection: [Errno 8] nodename nor servname provided, or not known

During handling of the above exception, another exception occurred:

Traceback (most recent call last):
  File "/Users/rudra_sarkar/Documents/CNN_practice/5h_prac/TFODCourse/tfod_new/env/lib/python3.8/site-packages/requests/adapters.py", line 489, in send
    resp = conn.urlopen(
  File "/Users/rudra_sarkar/Documents/CNN_practice/5h_prac/TFODCourse/tfod_new/env/lib/python3.8/site-packages/urllib3/connectionpool.py", line 787, in urlopen
    retries = retries.increment(
  File "/Users/rudra_sarkar/Documents/CNN_practice/5h_prac/TFODCourse/tfod_new/env/lib/python3.8/site-packages/urllib3/util/retry.py", line 592, in increment
    raise MaxRetryError(_pool, url, error or ResponseError(cause))
urllib3.exceptions.MaxRetryError: HTTPSConnectionPool(host='api.wandb.ai', port=443): Max retries exceeded with url: /graphql (Caused by NewConnectionError('<urllib3.connection.HTTPSConnection object at 0x1578ed5e0>: Failed to establish a new connection: [Errno 8] nodename nor servname provided, or not known'))

During handling of the above exception, another exception occurred:

Traceback (most recent call last):
  File "/Users/rudra_sarkar/Documents/CNN_practice/5h_prac/TFODCourse/tfod_new/env/lib/python3.8/site-packages/wandb/sdk/lib/retry.py", line 134, in __call__
    result = self._call_fn(*args, **kwargs)
  File "/Users/rudra_sarkar/Documents/CNN_practice/5h_prac/TFODCourse/tfod_new/env/lib/python3.8/site-packages/wandb/apis/public/api.py", line 79, in execute
    return self._client.execute(*args, **kwargs)
  File "/Users/rudra_sarkar/Documents/CNN_practice/5h_prac/TFODCourse/tfod_new/env/lib/python3.8/site-packages/wandb/vendor/gql-0.2.0/wandb_gql/client.py", line 52, in execute
    result = self._get_result(document, *args, **kwargs)
  File "/Users/rudra_sarkar/Documents/CNN_practice/5h_prac/TFODCourse/tfod_new/env/lib/python3.8/site-packages/wandb/vendor/gql-0.2.0/wandb_gql/client.py", line 60, in _get_result
    return self.transport.execute(document, *args, **kwargs)
  File "/Users/rudra_sarkar/Documents/CNN_practice/5h_prac/TFODCourse/tfod_new/env/lib/python3.8/site-packages/wandb/sdk/lib/gql_request.py", line 58, in execute
    request = self.session.post(self.url, **post_args)
  File "/Users/rudra_sarkar/Documents/CNN_practice/5h_prac/TFODCourse/tfod_new/env/lib/python3.8/site-packages/requests/sessions.py", line 635, in post
    return self.request("POST", url, data=data, json=json, **kwargs)
  File "/Users/rudra_sarkar/Documents/CNN_practice/5h_prac/TFODCourse/tfod_new/env/lib/python3.8/site-packages/requests/sessions.py", line 587, in request
    resp = self.send(prep, **send_kwargs)
  File "/Users/rudra_sarkar/Documents/CNN_practice/5h_prac/TFODCourse/tfod_new/env/lib/python3.8/site-packages/requests/sessions.py", line 701, in send
    r = adapter.send(request, **kwargs)
  File "/Users/rudra_sarkar/Documents/CNN_practice/5h_prac/TFODCourse/tfod_new/env/lib/python3.8/site-packages/requests/adapters.py", line 565, in send
    raise ConnectionError(e, request=request)
requests.exceptions.ConnectionError: HTTPSConnectionPool(host='api.wandb.ai', port=443): Max retries exceeded with url: /graphql (Caused by NewConnectionError('<urllib3.connection.HTTPSConnection object at 0x1578ed5e0>: Failed to establish a new connection: [Errno 8] nodename nor servname provided, or not known'))
2025-03-16 16:48:26,485 INFO    Thread-10 :47473 [wandb_run.py:_config_callback():1261] config_cb ('_wandb', 'visualize', 'Confusion matrix') {'panel_type': 'Vega2', 'panel_config': {'panelDefId': 'wandb/confusion_matrix/v1', 'fieldSettings': {'Actual': 'Actual', 'Predicted': 'Predicted', 'nPredictions': 'nPredictions'}, 'stringSettings': {'title': 'Confusion Matrix Curve'}, 'transform': {'name': 'tableWithLeafColNames'}, 'userQuery': {'queryFields': [{'name': 'runSets', 'args': [{'name': 'runSets', 'value': '${runSets}'}], 'fields': [{'name': 'id', 'fields': []}, {'name': 'name', 'fields': []}, {'name': '_defaultColorIndex', 'fields': []}, {'name': 'summaryTable', 'args': [{'name': 'tableKey', 'value': 'Confusion matrix_table'}], 'fields': []}]}]}}} None
2025-03-16 16:48:45,689 INFO    Thread-10 :47473 [wandb_run.py:_config_callback():1261] config_cb ('_wandb', 'visualize', 'Confusion matrix') {'panel_type': 'Vega2', 'panel_config': {'panelDefId': 'wandb/confusion_matrix/v1', 'fieldSettings': {'Actual': 'Actual', 'Predicted': 'Predicted', 'nPredictions': 'nPredictions'}, 'stringSettings': {'title': 'Confusion Matrix Curve'}, 'transform': {'name': 'tableWithLeafColNames'}, 'userQuery': {'queryFields': [{'name': 'runSets', 'args': [{'name': 'runSets', 'value': '${runSets}'}], 'fields': [{'name': 'id', 'fields': []}, {'name': 'name', 'fields': []}, {'name': '_defaultColorIndex', 'fields': []}, {'name': 'summaryTable', 'args': [{'name': 'tableKey', 'value': 'Confusion matrix_table'}], 'fields': []}]}]}}} None
2025-03-16 16:49:08,521 INFO    Thread-10 :47473 [wandb_run.py:_config_callback():1261] config_cb ('_wandb', 'visualize', 'Confusion matrix') {'panel_type': 'Vega2', 'panel_config': {'panelDefId': 'wandb/confusion_matrix/v1', 'fieldSettings': {'Actual': 'Actual', 'Predicted': 'Predicted', 'nPredictions': 'nPredictions'}, 'stringSettings': {'title': 'Confusion Matrix Curve'}, 'transform': {'name': 'tableWithLeafColNames'}, 'userQuery': {'queryFields': [{'name': 'runSets', 'args': [{'name': 'runSets', 'value': '${runSets}'}], 'fields': [{'name': 'id', 'fields': []}, {'name': 'name', 'fields': []}, {'name': '_defaultColorIndex', 'fields': []}, {'name': 'summaryTable', 'args': [{'name': 'tableKey', 'value': 'Confusion matrix_table'}], 'fields': []}]}]}}} None
2025-03-16 16:49:20,085 INFO    Thread-10 :47473 [wandb_run.py:_config_callback():1261] config_cb ('_wandb', 'visualize', 'Confusion matrix') {'panel_type': 'Vega2', 'panel_config': {'panelDefId': 'wandb/confusion_matrix/v1', 'fieldSettings': {'Actual': 'Actual', 'Predicted': 'Predicted', 'nPredictions': 'nPredictions'}, 'stringSettings': {'title': 'Confusion Matrix Curve'}, 'transform': {'name': 'tableWithLeafColNames'}, 'userQuery': {'queryFields': [{'name': 'runSets', 'args': [{'name': 'runSets', 'value': '${runSets}'}], 'fields': [{'name': 'id', 'fields': []}, {'name': 'name', 'fields': []}, {'name': '_defaultColorIndex', 'fields': []}, {'name': 'summaryTable', 'args': [{'name': 'tableKey', 'value': 'Confusion matrix_table'}], 'fields': []}]}]}}} None
2025-03-16 16:49:24,045 INFO    Thread-10 :47473 [wandb_run.py:_config_callback():1261] config_cb ('_wandb', 'visualize', 'Confusion matrix') {'panel_type': 'Vega2', 'panel_config': {'panelDefId': 'wandb/confusion_matrix/v1', 'fieldSettings': {'Actual': 'Actual', 'Predicted': 'Predicted', 'nPredictions': 'nPredictions'}, 'stringSettings': {'title': 'Confusion Matrix Curve'}, 'transform': {'name': 'tableWithLeafColNames'}, 'userQuery': {'queryFields': [{'name': 'runSets', 'args': [{'name': 'runSets', 'value': '${runSets}'}], 'fields': [{'name': 'id', 'fields': []}, {'name': 'name', 'fields': []}, {'name': '_defaultColorIndex', 'fields': []}, {'name': 'summaryTable', 'args': [{'name': 'tableKey', 'value': 'Confusion matrix_table'}], 'fields': []}]}]}}} None
2025-03-16 16:49:25,573 INFO    MainThread:47473 [wandb_run.py:_finish():2112] finishing run da24d008-iit-madras/da24d008-assignment1/endsj1id
2025-03-16 16:49:25,574 INFO    MainThread:47473 [wandb_run.py:_atexit_cleanup():2340] got exitcode: 0
2025-03-16 16:49:25,574 INFO    MainThread:47473 [wandb_run.py:_restore():2322] restore
2025-03-16 16:49:25,574 INFO    MainThread:47473 [wandb_run.py:_restore():2328] restore done
2025-03-16 16:49:25,575 INFO    Thread-10 :47473 [wandb_run.py:_finish():2112] finishing run da24d008-iit-madras/da24d008-assignment1/endsj1id
