Model Summary
---------------------------------------
hidden0
weights : (784, 784)
bias : (784, 1)
activation : relu
---------------------------------------
hidden1
weights : (10, 784)
bias : (10, 1)
activation : relu
---------------------------------------
output2
weights : (10, 10)
bias : (10, 1)
activation : softmax
---------------------------------------
Total Number of Parameters : 623400
Loss : 0.1      Train accuracy : 11.25      Validation accuracy : 10.41
-------------------------------------------------------------------------------------
Loss : 0.09      Train accuracy : 11.2      Validation accuracy : 10.37
-------------------------------------------------------------------------------------
Loss : 0.09      Train accuracy : 10.58      Validation accuracy : 10.27
-------------------------------------------------------------------------------------
Loss : 0.09      Train accuracy : 10.38      Validation accuracy : 10.45
-------------------------------------------------------------------------------------
[34m[1mwandb[0m: [32m[41mERROR[0m Error while calling W&B API: could not find agent 28yt4v5q during agentHeartbeat (<Response [404]>)
Exception in thread Thread-2:
Traceback (most recent call last):
  File "/Users/rudra_sarkar/Documents/CNN_practice/5h_prac/TFODCourse/tfod_new/env/lib/python3.8/site-packages/wandb/sdk/internal/internal_api.py", line 3144, in agent_heartbeat
    response = self.gql(
  File "/Users/rudra_sarkar/Documents/CNN_practice/5h_prac/TFODCourse/tfod_new/env/lib/python3.8/site-packages/wandb/sdk/internal/internal_api.py", line 370, in gql
    ret = self._retry_gql(
  File "/Users/rudra_sarkar/Documents/CNN_practice/5h_prac/TFODCourse/tfod_new/env/lib/python3.8/site-packages/wandb/sdk/lib/retry.py", line 134, in __call__
    result = self._call_fn(*args, **kwargs)
  File "/Users/rudra_sarkar/Documents/CNN_practice/5h_prac/TFODCourse/tfod_new/env/lib/python3.8/site-packages/wandb/sdk/internal/internal_api.py", line 398, in execute
    return self.client.execute(*args, **kwargs)  # type: ignore
  File "/Users/rudra_sarkar/Documents/CNN_practice/5h_prac/TFODCourse/tfod_new/env/lib/python3.8/site-packages/wandb/vendor/gql-0.2.0/wandb_gql/client.py", line 52, in execute
    result = self._get_result(document, *args, **kwargs)
  File "/Users/rudra_sarkar/Documents/CNN_practice/5h_prac/TFODCourse/tfod_new/env/lib/python3.8/site-packages/wandb/vendor/gql-0.2.0/wandb_gql/client.py", line 60, in _get_result
    return self.transport.execute(document, *args, **kwargs)
  File "/Users/rudra_sarkar/Documents/CNN_practice/5h_prac/TFODCourse/tfod_new/env/lib/python3.8/site-packages/wandb/sdk/lib/gql_request.py", line 59, in execute
    request.raise_for_status()
  File "/Users/rudra_sarkar/Documents/CNN_practice/5h_prac/TFODCourse/tfod_new/env/lib/python3.8/site-packages/requests/models.py", line 1021, in raise_for_status
    raise HTTPError(http_error_msg, response=self)
requests.exceptions.HTTPError: 404 Client Error: Not Found for url: https://api.wandb.ai/graphql

During handling of the above exception, another exception occurred:

Traceback (most recent call last):
  File "/Users/rudra_sarkar/Documents/CNN_practice/5h_prac/TFODCourse/tfod_new/env/lib/python3.8/threading.py", line 932, in _bootstrap_inner
    self.run()
  File "/Users/rudra_sarkar/Documents/CNN_practice/5h_prac/TFODCourse/tfod_new/env/lib/python3.8/threading.py", line 870, in run
    self._target(*self._args, **self._kwargs)
  File "/Users/rudra_sarkar/Documents/CNN_practice/5h_prac/TFODCourse/tfod_new/env/lib/python3.8/site-packages/wandb/agents/pyagent.py", line 165, in _heartbeat
    commands = self._api.agent_heartbeat(self._agent_id, {}, run_status)
  File "/Users/rudra_sarkar/Documents/CNN_practice/5h_prac/TFODCourse/tfod_new/env/lib/python3.8/site-packages/wandb/apis/internal.py", line 161, in agent_heartbeat
    return self.api.agent_heartbeat(*args, **kwargs)
  File "/Users/rudra_sarkar/Documents/CNN_practice/5h_prac/TFODCourse/tfod_new/env/lib/python3.8/site-packages/wandb/sdk/internal/internal_api.py", line 3155, in agent_heartbeat
    message = ast.literal_eval(e.args[0])["message"]
  File "/Users/rudra_sarkar/Documents/CNN_practice/5h_prac/TFODCourse/tfod_new/env/lib/python3.8/ast.py", line 59, in literal_eval
    node_or_string = parse(node_or_string, mode='eval')
  File "/Users/rudra_sarkar/Documents/CNN_practice/5h_prac/TFODCourse/tfod_new/env/lib/python3.8/ast.py", line 47, in parse
    return compile(source, filename, mode, flags,
  File "<unknown>", line 1
    404 Client Error: Not Found for url: https://api.wandb.ai/graphql
        ^
SyntaxError: invalid syntax
