2025-03-15 12:47:13,957 INFO    Thread-16 :21771 [wandb_setup.py:_flush():67] Current SDK version is 0.19.8
2025-03-15 12:47:13,957 INFO    Thread-16 :21771 [wandb_setup.py:_flush():67] Configure stats pid to 21771
2025-03-15 12:47:13,957 INFO    Thread-16 :21771 [wandb_setup.py:_flush():67] Loading settings from /Users/rudra_sarkar/.config/wandb/settings
2025-03-15 12:47:13,958 INFO    Thread-16 :21771 [wandb_setup.py:_flush():67] Loading settings from /Users/rudra_sarkar/Documents/PhD IIT Madras/Intro to Deep Learning M Khapra DA6401/DA6401 Assignment/da6401_assignment1/wandb/settings
2025-03-15 12:47:13,958 INFO    Thread-16 :21771 [wandb_setup.py:_flush():67] Loading settings from environment variables
2025-03-15 12:47:13,958 INFO    Thread-16 :21771 [wandb_init.py:setup_run_log_directory():647] Logging user logs to /Users/rudra_sarkar/Documents/PhD IIT Madras/Intro to Deep Learning M Khapra DA6401/DA6401 Assignment/da6401_assignment1/wandb/run-20250315_124713-xf9las1e/logs/debug.log
2025-03-15 12:47:13,958 INFO    Thread-16 :21771 [wandb_init.py:setup_run_log_directory():648] Logging internal logs to /Users/rudra_sarkar/Documents/PhD IIT Madras/Intro to Deep Learning M Khapra DA6401/DA6401 Assignment/da6401_assignment1/wandb/run-20250315_124713-xf9las1e/logs/debug-internal.log
2025-03-15 12:47:13,958 INFO    Thread-16 :21771 [wandb_init.py:init():761] calling init triggers
2025-03-15 12:47:13,958 INFO    Thread-16 :21771 [wandb_init.py:init():766] wandb.init called with sweep_config: {'activation': 'sigmoid', 'batch_size': 256, 'beta1': 0.940924452556808, 'beta2': 0.9545123665805156, 'epochs': 500, 'hidden_size': [784, 32], 'learning_rate': 0.0007991261589508825, 'loss': 'cross_entropy', 'momentum': 0.8063373892553518, 'optimizer': 'sgd', 'weight_decay': 0.00014940655080386455, 'weight_init': 'xavier'}
config: {'epochs': 1000, 'batch_size': 512, 'loss': 'mean_squared_error', 'optimizer': 'nag', 'learning_rate': 0.0032812590822565283, 'weight_init': 'xavier', 'hidden_size': [784], 'num_layers': 1, 'input_size': 784, 'output_size': 10, 'beta': 0.5, 'activation': 'relu', 'weight_decay': 0.0004066602839565767, 'beta1': 0.9233438776054892, 'beta2': 0.9956172013639096, 'epsilon': 1e-06, 'momentum': 0.5487642823109323, 'wandb_entity': 'da24d008-iit-madras', 'wandb_project': 'da24d008-assignment1', 'wandb_sweep': True, 'sweep_id': None, 'dataset': 'fashion_mnist', '_wandb': {}}
2025-03-15 12:47:13,958 INFO    Thread-16 :21771 [wandb_init.py:init():784] starting backend
2025-03-15 12:47:13,958 INFO    Thread-16 :21771 [wandb_init.py:init():788] sending inform_init request
2025-03-15 12:47:13,963 INFO    Thread-16 :21771 [backend.py:_multiprocessing_setup():101] multiprocessing start_methods=spawn,fork,forkserver, using: spawn
2025-03-15 12:47:13,963 INFO    Thread-16 :21771 [wandb_init.py:init():798] backend started and connected
2025-03-15 12:47:13,965 INFO    Thread-16 :21771 [wandb_run.py:_config_callback():1261] config_cb None None {'activation': 'sigmoid', 'batch_size': 256, 'beta1': 0.940924452556808, 'beta2': 0.9545123665805156, 'epochs': 500, 'hidden_size': [784, 32], 'learning_rate': 0.0007991261589508825, 'loss': 'cross_entropy', 'momentum': 0.8063373892553518, 'optimizer': 'sgd', 'weight_decay': 0.00014940655080386455, 'weight_init': 'xavier'}
2025-03-15 12:47:13,975 INFO    Thread-16 :21771 [wandb_init.py:init():891] updated telemetry
2025-03-15 12:47:14,019 INFO    Thread-16 :21771 [wandb_init.py:init():915] communicating run to backend with 90.0 second timeout
2025-03-15 12:47:14,487 INFO    Thread-16 :21771 [wandb_init.py:init():990] starting run threads in backend
2025-03-15 12:47:15,071 INFO    Thread-16 :21771 [wandb_run.py:_console_start():2375] atexit reg
2025-03-15 12:47:15,072 INFO    Thread-16 :21771 [wandb_run.py:_redirect():2227] redirect: wrap_raw
2025-03-15 12:47:15,073 INFO    Thread-16 :21771 [wandb_run.py:_redirect():2292] Wrapping output streams.
2025-03-15 12:47:15,074 INFO    Thread-16 :21771 [wandb_run.py:_redirect():2315] Redirects installed.
2025-03-15 12:47:15,076 INFO    Thread-16 :21771 [wandb_init.py:init():1032] run started, returning control to user process
2025-03-15 12:47:33,588 INFO    Thread-16 :21771 [wandb_run.py:_config_callback():1261] config_cb ('_wandb', 'visualize', 'Confusion matrix') {'panel_type': 'Vega2', 'panel_config': {'panelDefId': 'wandb/confusion_matrix/v1', 'fieldSettings': {'Actual': 'Actual', 'Predicted': 'Predicted', 'nPredictions': 'nPredictions'}, 'stringSettings': {'title': 'Confusion Matrix Curve'}, 'transform': {'name': 'tableWithLeafColNames'}, 'userQuery': {'queryFields': [{'name': 'runSets', 'args': [{'name': 'runSets', 'value': '${runSets}'}], 'fields': [{'name': 'id', 'fields': []}, {'name': 'name', 'fields': []}, {'name': '_defaultColorIndex', 'fields': []}, {'name': 'summaryTable', 'args': [{'name': 'tableKey', 'value': 'Confusion matrix_table'}], 'fields': []}]}]}}} None
2025-03-15 12:48:18,939 INFO    Thread-16 :21771 [wandb_run.py:_config_callback():1261] config_cb ('_wandb', 'visualize', 'Confusion matrix') {'panel_type': 'Vega2', 'panel_config': {'panelDefId': 'wandb/confusion_matrix/v1', 'fieldSettings': {'Actual': 'Actual', 'Predicted': 'Predicted', 'nPredictions': 'nPredictions'}, 'stringSettings': {'title': 'Confusion Matrix Curve'}, 'transform': {'name': 'tableWithLeafColNames'}, 'userQuery': {'queryFields': [{'name': 'runSets', 'args': [{'name': 'runSets', 'value': '${runSets}'}], 'fields': [{'name': 'id', 'fields': []}, {'name': 'name', 'fields': []}, {'name': '_defaultColorIndex', 'fields': []}, {'name': 'summaryTable', 'args': [{'name': 'tableKey', 'value': 'Confusion matrix_table'}], 'fields': []}]}]}}} None
2025-03-15 12:49:05,786 INFO    Thread-16 :21771 [wandb_run.py:_config_callback():1261] config_cb ('_wandb', 'visualize', 'Confusion matrix') {'panel_type': 'Vega2', 'panel_config': {'panelDefId': 'wandb/confusion_matrix/v1', 'fieldSettings': {'Actual': 'Actual', 'Predicted': 'Predicted', 'nPredictions': 'nPredictions'}, 'stringSettings': {'title': 'Confusion Matrix Curve'}, 'transform': {'name': 'tableWithLeafColNames'}, 'userQuery': {'queryFields': [{'name': 'runSets', 'args': [{'name': 'runSets', 'value': '${runSets}'}], 'fields': [{'name': 'id', 'fields': []}, {'name': 'name', 'fields': []}, {'name': '_defaultColorIndex', 'fields': []}, {'name': 'summaryTable', 'args': [{'name': 'tableKey', 'value': 'Confusion matrix_table'}], 'fields': []}]}]}}} None
2025-03-15 12:49:47,720 INFO    Thread-16 :21771 [wandb_run.py:_config_callback():1261] config_cb ('_wandb', 'visualize', 'Confusion matrix') {'panel_type': 'Vega2', 'panel_config': {'panelDefId': 'wandb/confusion_matrix/v1', 'fieldSettings': {'Actual': 'Actual', 'Predicted': 'Predicted', 'nPredictions': 'nPredictions'}, 'stringSettings': {'title': 'Confusion Matrix Curve'}, 'transform': {'name': 'tableWithLeafColNames'}, 'userQuery': {'queryFields': [{'name': 'runSets', 'args': [{'name': 'runSets', 'value': '${runSets}'}], 'fields': [{'name': 'id', 'fields': []}, {'name': 'name', 'fields': []}, {'name': '_defaultColorIndex', 'fields': []}, {'name': 'summaryTable', 'args': [{'name': 'tableKey', 'value': 'Confusion matrix_table'}], 'fields': []}]}]}}} None
2025-03-15 12:50:29,838 INFO    Thread-16 :21771 [wandb_run.py:_config_callback():1261] config_cb ('_wandb', 'visualize', 'Confusion matrix') {'panel_type': 'Vega2', 'panel_config': {'panelDefId': 'wandb/confusion_matrix/v1', 'fieldSettings': {'Actual': 'Actual', 'Predicted': 'Predicted', 'nPredictions': 'nPredictions'}, 'stringSettings': {'title': 'Confusion Matrix Curve'}, 'transform': {'name': 'tableWithLeafColNames'}, 'userQuery': {'queryFields': [{'name': 'runSets', 'args': [{'name': 'runSets', 'value': '${runSets}'}], 'fields': [{'name': 'id', 'fields': []}, {'name': 'name', 'fields': []}, {'name': '_defaultColorIndex', 'fields': []}, {'name': 'summaryTable', 'args': [{'name': 'tableKey', 'value': 'Confusion matrix_table'}], 'fields': []}]}]}}} None
2025-03-15 12:51:12,881 INFO    Thread-16 :21771 [wandb_run.py:_config_callback():1261] config_cb ('_wandb', 'visualize', 'Confusion matrix') {'panel_type': 'Vega2', 'panel_config': {'panelDefId': 'wandb/confusion_matrix/v1', 'fieldSettings': {'Actual': 'Actual', 'Predicted': 'Predicted', 'nPredictions': 'nPredictions'}, 'stringSettings': {'title': 'Confusion Matrix Curve'}, 'transform': {'name': 'tableWithLeafColNames'}, 'userQuery': {'queryFields': [{'name': 'runSets', 'args': [{'name': 'runSets', 'value': '${runSets}'}], 'fields': [{'name': 'id', 'fields': []}, {'name': 'name', 'fields': []}, {'name': '_defaultColorIndex', 'fields': []}, {'name': 'summaryTable', 'args': [{'name': 'tableKey', 'value': 'Confusion matrix_table'}], 'fields': []}]}]}}} None
2025-03-15 12:51:55,245 INFO    Thread-16 :21771 [wandb_run.py:_config_callback():1261] config_cb ('_wandb', 'visualize', 'Confusion matrix') {'panel_type': 'Vega2', 'panel_config': {'panelDefId': 'wandb/confusion_matrix/v1', 'fieldSettings': {'Actual': 'Actual', 'Predicted': 'Predicted', 'nPredictions': 'nPredictions'}, 'stringSettings': {'title': 'Confusion Matrix Curve'}, 'transform': {'name': 'tableWithLeafColNames'}, 'userQuery': {'queryFields': [{'name': 'runSets', 'args': [{'name': 'runSets', 'value': '${runSets}'}], 'fields': [{'name': 'id', 'fields': []}, {'name': 'name', 'fields': []}, {'name': '_defaultColorIndex', 'fields': []}, {'name': 'summaryTable', 'args': [{'name': 'tableKey', 'value': 'Confusion matrix_table'}], 'fields': []}]}]}}} None
2025-03-15 12:52:37,657 INFO    Thread-16 :21771 [wandb_run.py:_config_callback():1261] config_cb ('_wandb', 'visualize', 'Confusion matrix') {'panel_type': 'Vega2', 'panel_config': {'panelDefId': 'wandb/confusion_matrix/v1', 'fieldSettings': {'Actual': 'Actual', 'Predicted': 'Predicted', 'nPredictions': 'nPredictions'}, 'stringSettings': {'title': 'Confusion Matrix Curve'}, 'transform': {'name': 'tableWithLeafColNames'}, 'userQuery': {'queryFields': [{'name': 'runSets', 'args': [{'name': 'runSets', 'value': '${runSets}'}], 'fields': [{'name': 'id', 'fields': []}, {'name': 'name', 'fields': []}, {'name': '_defaultColorIndex', 'fields': []}, {'name': 'summaryTable', 'args': [{'name': 'tableKey', 'value': 'Confusion matrix_table'}], 'fields': []}]}]}}} None
2025-03-15 12:53:19,622 INFO    Thread-16 :21771 [wandb_run.py:_config_callback():1261] config_cb ('_wandb', 'visualize', 'Confusion matrix') {'panel_type': 'Vega2', 'panel_config': {'panelDefId': 'wandb/confusion_matrix/v1', 'fieldSettings': {'Actual': 'Actual', 'Predicted': 'Predicted', 'nPredictions': 'nPredictions'}, 'stringSettings': {'title': 'Confusion Matrix Curve'}, 'transform': {'name': 'tableWithLeafColNames'}, 'userQuery': {'queryFields': [{'name': 'runSets', 'args': [{'name': 'runSets', 'value': '${runSets}'}], 'fields': [{'name': 'id', 'fields': []}, {'name': 'name', 'fields': []}, {'name': '_defaultColorIndex', 'fields': []}, {'name': 'summaryTable', 'args': [{'name': 'tableKey', 'value': 'Confusion matrix_table'}], 'fields': []}]}]}}} None
2025-03-15 12:54:02,933 INFO    Thread-16 :21771 [wandb_run.py:_config_callback():1261] config_cb ('_wandb', 'visualize', 'Confusion matrix') {'panel_type': 'Vega2', 'panel_config': {'panelDefId': 'wandb/confusion_matrix/v1', 'fieldSettings': {'Actual': 'Actual', 'Predicted': 'Predicted', 'nPredictions': 'nPredictions'}, 'stringSettings': {'title': 'Confusion Matrix Curve'}, 'transform': {'name': 'tableWithLeafColNames'}, 'userQuery': {'queryFields': [{'name': 'runSets', 'args': [{'name': 'runSets', 'value': '${runSets}'}], 'fields': [{'name': 'id', 'fields': []}, {'name': 'name', 'fields': []}, {'name': '_defaultColorIndex', 'fields': []}, {'name': 'summaryTable', 'args': [{'name': 'tableKey', 'value': 'Confusion matrix_table'}], 'fields': []}]}]}}} None
2025-03-15 12:54:50,598 INFO    Thread-16 :21771 [wandb_run.py:_config_callback():1261] config_cb ('_wandb', 'visualize', 'Confusion matrix') {'panel_type': 'Vega2', 'panel_config': {'panelDefId': 'wandb/confusion_matrix/v1', 'fieldSettings': {'Actual': 'Actual', 'Predicted': 'Predicted', 'nPredictions': 'nPredictions'}, 'stringSettings': {'title': 'Confusion Matrix Curve'}, 'transform': {'name': 'tableWithLeafColNames'}, 'userQuery': {'queryFields': [{'name': 'runSets', 'args': [{'name': 'runSets', 'value': '${runSets}'}], 'fields': [{'name': 'id', 'fields': []}, {'name': 'name', 'fields': []}, {'name': '_defaultColorIndex', 'fields': []}, {'name': 'summaryTable', 'args': [{'name': 'tableKey', 'value': 'Confusion matrix_table'}], 'fields': []}]}]}}} None
2025-03-15 12:55:35,946 INFO    Thread-16 :21771 [wandb_run.py:_config_callback():1261] config_cb ('_wandb', 'visualize', 'Confusion matrix') {'panel_type': 'Vega2', 'panel_config': {'panelDefId': 'wandb/confusion_matrix/v1', 'fieldSettings': {'Actual': 'Actual', 'Predicted': 'Predicted', 'nPredictions': 'nPredictions'}, 'stringSettings': {'title': 'Confusion Matrix Curve'}, 'transform': {'name': 'tableWithLeafColNames'}, 'userQuery': {'queryFields': [{'name': 'runSets', 'args': [{'name': 'runSets', 'value': '${runSets}'}], 'fields': [{'name': 'id', 'fields': []}, {'name': 'name', 'fields': []}, {'name': '_defaultColorIndex', 'fields': []}, {'name': 'summaryTable', 'args': [{'name': 'tableKey', 'value': 'Confusion matrix_table'}], 'fields': []}]}]}}} None
2025-03-15 12:56:20,893 INFO    Thread-16 :21771 [wandb_run.py:_config_callback():1261] config_cb ('_wandb', 'visualize', 'Confusion matrix') {'panel_type': 'Vega2', 'panel_config': {'panelDefId': 'wandb/confusion_matrix/v1', 'fieldSettings': {'Actual': 'Actual', 'Predicted': 'Predicted', 'nPredictions': 'nPredictions'}, 'stringSettings': {'title': 'Confusion Matrix Curve'}, 'transform': {'name': 'tableWithLeafColNames'}, 'userQuery': {'queryFields': [{'name': 'runSets', 'args': [{'name': 'runSets', 'value': '${runSets}'}], 'fields': [{'name': 'id', 'fields': []}, {'name': 'name', 'fields': []}, {'name': '_defaultColorIndex', 'fields': []}, {'name': 'summaryTable', 'args': [{'name': 'tableKey', 'value': 'Confusion matrix_table'}], 'fields': []}]}]}}} None
2025-03-15 12:57:05,385 INFO    Thread-16 :21771 [wandb_run.py:_config_callback():1261] config_cb ('_wandb', 'visualize', 'Confusion matrix') {'panel_type': 'Vega2', 'panel_config': {'panelDefId': 'wandb/confusion_matrix/v1', 'fieldSettings': {'Actual': 'Actual', 'Predicted': 'Predicted', 'nPredictions': 'nPredictions'}, 'stringSettings': {'title': 'Confusion Matrix Curve'}, 'transform': {'name': 'tableWithLeafColNames'}, 'userQuery': {'queryFields': [{'name': 'runSets', 'args': [{'name': 'runSets', 'value': '${runSets}'}], 'fields': [{'name': 'id', 'fields': []}, {'name': 'name', 'fields': []}, {'name': '_defaultColorIndex', 'fields': []}, {'name': 'summaryTable', 'args': [{'name': 'tableKey', 'value': 'Confusion matrix_table'}], 'fields': []}]}]}}} None
2025-03-15 12:57:50,243 INFO    Thread-16 :21771 [wandb_run.py:_config_callback():1261] config_cb ('_wandb', 'visualize', 'Confusion matrix') {'panel_type': 'Vega2', 'panel_config': {'panelDefId': 'wandb/confusion_matrix/v1', 'fieldSettings': {'Actual': 'Actual', 'Predicted': 'Predicted', 'nPredictions': 'nPredictions'}, 'stringSettings': {'title': 'Confusion Matrix Curve'}, 'transform': {'name': 'tableWithLeafColNames'}, 'userQuery': {'queryFields': [{'name': 'runSets', 'args': [{'name': 'runSets', 'value': '${runSets}'}], 'fields': [{'name': 'id', 'fields': []}, {'name': 'name', 'fields': []}, {'name': '_defaultColorIndex', 'fields': []}, {'name': 'summaryTable', 'args': [{'name': 'tableKey', 'value': 'Confusion matrix_table'}], 'fields': []}]}]}}} None
2025-03-15 12:58:34,769 INFO    Thread-16 :21771 [wandb_run.py:_config_callback():1261] config_cb ('_wandb', 'visualize', 'Confusion matrix') {'panel_type': 'Vega2', 'panel_config': {'panelDefId': 'wandb/confusion_matrix/v1', 'fieldSettings': {'Actual': 'Actual', 'Predicted': 'Predicted', 'nPredictions': 'nPredictions'}, 'stringSettings': {'title': 'Confusion Matrix Curve'}, 'transform': {'name': 'tableWithLeafColNames'}, 'userQuery': {'queryFields': [{'name': 'runSets', 'args': [{'name': 'runSets', 'value': '${runSets}'}], 'fields': [{'name': 'id', 'fields': []}, {'name': 'name', 'fields': []}, {'name': '_defaultColorIndex', 'fields': []}, {'name': 'summaryTable', 'args': [{'name': 'tableKey', 'value': 'Confusion matrix_table'}], 'fields': []}]}]}}} None
2025-03-15 13:04:58,791 INFO    Thread-16 :21771 [wandb_run.py:_config_callback():1261] config_cb ('_wandb', 'visualize', 'Confusion matrix') {'panel_type': 'Vega2', 'panel_config': {'panelDefId': 'wandb/confusion_matrix/v1', 'fieldSettings': {'Actual': 'Actual', 'Predicted': 'Predicted', 'nPredictions': 'nPredictions'}, 'stringSettings': {'title': 'Confusion Matrix Curve'}, 'transform': {'name': 'tableWithLeafColNames'}, 'userQuery': {'queryFields': [{'name': 'runSets', 'args': [{'name': 'runSets', 'value': '${runSets}'}], 'fields': [{'name': 'id', 'fields': []}, {'name': 'name', 'fields': []}, {'name': '_defaultColorIndex', 'fields': []}, {'name': 'summaryTable', 'args': [{'name': 'tableKey', 'value': 'Confusion matrix_table'}], 'fields': []}]}]}}} None
2025-03-15 13:05:40,390 INFO    Thread-16 :21771 [wandb_run.py:_config_callback():1261] config_cb ('_wandb', 'visualize', 'Confusion matrix') {'panel_type': 'Vega2', 'panel_config': {'panelDefId': 'wandb/confusion_matrix/v1', 'fieldSettings': {'Actual': 'Actual', 'Predicted': 'Predicted', 'nPredictions': 'nPredictions'}, 'stringSettings': {'title': 'Confusion Matrix Curve'}, 'transform': {'name': 'tableWithLeafColNames'}, 'userQuery': {'queryFields': [{'name': 'runSets', 'args': [{'name': 'runSets', 'value': '${runSets}'}], 'fields': [{'name': 'id', 'fields': []}, {'name': 'name', 'fields': []}, {'name': '_defaultColorIndex', 'fields': []}, {'name': 'summaryTable', 'args': [{'name': 'tableKey', 'value': 'Confusion matrix_table'}], 'fields': []}]}]}}} None
2025-03-15 13:06:17,711 INFO    Thread-16 :21771 [wandb_run.py:_config_callback():1261] config_cb ('_wandb', 'visualize', 'Confusion matrix') {'panel_type': 'Vega2', 'panel_config': {'panelDefId': 'wandb/confusion_matrix/v1', 'fieldSettings': {'Actual': 'Actual', 'Predicted': 'Predicted', 'nPredictions': 'nPredictions'}, 'stringSettings': {'title': 'Confusion Matrix Curve'}, 'transform': {'name': 'tableWithLeafColNames'}, 'userQuery': {'queryFields': [{'name': 'runSets', 'args': [{'name': 'runSets', 'value': '${runSets}'}], 'fields': [{'name': 'id', 'fields': []}, {'name': 'name', 'fields': []}, {'name': '_defaultColorIndex', 'fields': []}, {'name': 'summaryTable', 'args': [{'name': 'tableKey', 'value': 'Confusion matrix_table'}], 'fields': []}]}]}}} None
2025-03-15 13:06:55,587 INFO    Thread-16 :21771 [wandb_run.py:_config_callback():1261] config_cb ('_wandb', 'visualize', 'Confusion matrix') {'panel_type': 'Vega2', 'panel_config': {'panelDefId': 'wandb/confusion_matrix/v1', 'fieldSettings': {'Actual': 'Actual', 'Predicted': 'Predicted', 'nPredictions': 'nPredictions'}, 'stringSettings': {'title': 'Confusion Matrix Curve'}, 'transform': {'name': 'tableWithLeafColNames'}, 'userQuery': {'queryFields': [{'name': 'runSets', 'args': [{'name': 'runSets', 'value': '${runSets}'}], 'fields': [{'name': 'id', 'fields': []}, {'name': 'name', 'fields': []}, {'name': '_defaultColorIndex', 'fields': []}, {'name': 'summaryTable', 'args': [{'name': 'tableKey', 'value': 'Confusion matrix_table'}], 'fields': []}]}]}}} None
2025-03-15 13:07:05,444 INFO    Thread-16 :21771 [wandb_run.py:_config_callback():1261] config_cb ('_wandb', 'visualize', 'Confusion matrix') {'panel_type': 'Vega2', 'panel_config': {'panelDefId': 'wandb/confusion_matrix/v1', 'fieldSettings': {'Actual': 'Actual', 'Predicted': 'Predicted', 'nPredictions': 'nPredictions'}, 'stringSettings': {'title': 'Confusion Matrix Curve'}, 'transform': {'name': 'tableWithLeafColNames'}, 'userQuery': {'queryFields': [{'name': 'runSets', 'args': [{'name': 'runSets', 'value': '${runSets}'}], 'fields': [{'name': 'id', 'fields': []}, {'name': 'name', 'fields': []}, {'name': '_defaultColorIndex', 'fields': []}, {'name': 'summaryTable', 'args': [{'name': 'tableKey', 'value': 'Confusion matrix_table'}], 'fields': []}]}]}}} None
2025-03-15 13:07:46,846 INFO    Thread-16 :21771 [wandb_run.py:_config_callback():1261] config_cb ('_wandb', 'visualize', 'Confusion matrix') {'panel_type': 'Vega2', 'panel_config': {'panelDefId': 'wandb/confusion_matrix/v1', 'fieldSettings': {'Actual': 'Actual', 'Predicted': 'Predicted', 'nPredictions': 'nPredictions'}, 'stringSettings': {'title': 'Confusion Matrix Curve'}, 'transform': {'name': 'tableWithLeafColNames'}, 'userQuery': {'queryFields': [{'name': 'runSets', 'args': [{'name': 'runSets', 'value': '${runSets}'}], 'fields': [{'name': 'id', 'fields': []}, {'name': 'name', 'fields': []}, {'name': '_defaultColorIndex', 'fields': []}, {'name': 'summaryTable', 'args': [{'name': 'tableKey', 'value': 'Confusion matrix_table'}], 'fields': []}]}]}}} None
2025-03-15 13:08:26,904 INFO    Thread-16 :21771 [wandb_run.py:_config_callback():1261] config_cb ('_wandb', 'visualize', 'Confusion matrix') {'panel_type': 'Vega2', 'panel_config': {'panelDefId': 'wandb/confusion_matrix/v1', 'fieldSettings': {'Actual': 'Actual', 'Predicted': 'Predicted', 'nPredictions': 'nPredictions'}, 'stringSettings': {'title': 'Confusion Matrix Curve'}, 'transform': {'name': 'tableWithLeafColNames'}, 'userQuery': {'queryFields': [{'name': 'runSets', 'args': [{'name': 'runSets', 'value': '${runSets}'}], 'fields': [{'name': 'id', 'fields': []}, {'name': 'name', 'fields': []}, {'name': '_defaultColorIndex', 'fields': []}, {'name': 'summaryTable', 'args': [{'name': 'tableKey', 'value': 'Confusion matrix_table'}], 'fields': []}]}]}}} None
2025-03-15 13:09:09,015 INFO    Thread-16 :21771 [wandb_run.py:_config_callback():1261] config_cb ('_wandb', 'visualize', 'Confusion matrix') {'panel_type': 'Vega2', 'panel_config': {'panelDefId': 'wandb/confusion_matrix/v1', 'fieldSettings': {'Actual': 'Actual', 'Predicted': 'Predicted', 'nPredictions': 'nPredictions'}, 'stringSettings': {'title': 'Confusion Matrix Curve'}, 'transform': {'name': 'tableWithLeafColNames'}, 'userQuery': {'queryFields': [{'name': 'runSets', 'args': [{'name': 'runSets', 'value': '${runSets}'}], 'fields': [{'name': 'id', 'fields': []}, {'name': 'name', 'fields': []}, {'name': '_defaultColorIndex', 'fields': []}, {'name': 'summaryTable', 'args': [{'name': 'tableKey', 'value': 'Confusion matrix_table'}], 'fields': []}]}]}}} None
2025-03-15 13:09:50,978 INFO    Thread-16 :21771 [wandb_run.py:_config_callback():1261] config_cb ('_wandb', 'visualize', 'Confusion matrix') {'panel_type': 'Vega2', 'panel_config': {'panelDefId': 'wandb/confusion_matrix/v1', 'fieldSettings': {'Actual': 'Actual', 'Predicted': 'Predicted', 'nPredictions': 'nPredictions'}, 'stringSettings': {'title': 'Confusion Matrix Curve'}, 'transform': {'name': 'tableWithLeafColNames'}, 'userQuery': {'queryFields': [{'name': 'runSets', 'args': [{'name': 'runSets', 'value': '${runSets}'}], 'fields': [{'name': 'id', 'fields': []}, {'name': 'name', 'fields': []}, {'name': '_defaultColorIndex', 'fields': []}, {'name': 'summaryTable', 'args': [{'name': 'tableKey', 'value': 'Confusion matrix_table'}], 'fields': []}]}]}}} None
2025-03-15 13:10:33,706 INFO    Thread-16 :21771 [wandb_run.py:_config_callback():1261] config_cb ('_wandb', 'visualize', 'Confusion matrix') {'panel_type': 'Vega2', 'panel_config': {'panelDefId': 'wandb/confusion_matrix/v1', 'fieldSettings': {'Actual': 'Actual', 'Predicted': 'Predicted', 'nPredictions': 'nPredictions'}, 'stringSettings': {'title': 'Confusion Matrix Curve'}, 'transform': {'name': 'tableWithLeafColNames'}, 'userQuery': {'queryFields': [{'name': 'runSets', 'args': [{'name': 'runSets', 'value': '${runSets}'}], 'fields': [{'name': 'id', 'fields': []}, {'name': 'name', 'fields': []}, {'name': '_defaultColorIndex', 'fields': []}, {'name': 'summaryTable', 'args': [{'name': 'tableKey', 'value': 'Confusion matrix_table'}], 'fields': []}]}]}}} None
2025-03-15 13:11:23,869 INFO    Thread-16 :21771 [wandb_run.py:_config_callback():1261] config_cb ('_wandb', 'visualize', 'Confusion matrix') {'panel_type': 'Vega2', 'panel_config': {'panelDefId': 'wandb/confusion_matrix/v1', 'fieldSettings': {'Actual': 'Actual', 'Predicted': 'Predicted', 'nPredictions': 'nPredictions'}, 'stringSettings': {'title': 'Confusion Matrix Curve'}, 'transform': {'name': 'tableWithLeafColNames'}, 'userQuery': {'queryFields': [{'name': 'runSets', 'args': [{'name': 'runSets', 'value': '${runSets}'}], 'fields': [{'name': 'id', 'fields': []}, {'name': 'name', 'fields': []}, {'name': '_defaultColorIndex', 'fields': []}, {'name': 'summaryTable', 'args': [{'name': 'tableKey', 'value': 'Confusion matrix_table'}], 'fields': []}]}]}}} None
2025-03-15 13:12:12,897 INFO    Thread-16 :21771 [wandb_run.py:_config_callback():1261] config_cb ('_wandb', 'visualize', 'Confusion matrix') {'panel_type': 'Vega2', 'panel_config': {'panelDefId': 'wandb/confusion_matrix/v1', 'fieldSettings': {'Actual': 'Actual', 'Predicted': 'Predicted', 'nPredictions': 'nPredictions'}, 'stringSettings': {'title': 'Confusion Matrix Curve'}, 'transform': {'name': 'tableWithLeafColNames'}, 'userQuery': {'queryFields': [{'name': 'runSets', 'args': [{'name': 'runSets', 'value': '${runSets}'}], 'fields': [{'name': 'id', 'fields': []}, {'name': 'name', 'fields': []}, {'name': '_defaultColorIndex', 'fields': []}, {'name': 'summaryTable', 'args': [{'name': 'tableKey', 'value': 'Confusion matrix_table'}], 'fields': []}]}]}}} None
2025-03-15 13:13:00,853 INFO    Thread-16 :21771 [wandb_run.py:_config_callback():1261] config_cb ('_wandb', 'visualize', 'Confusion matrix') {'panel_type': 'Vega2', 'panel_config': {'panelDefId': 'wandb/confusion_matrix/v1', 'fieldSettings': {'Actual': 'Actual', 'Predicted': 'Predicted', 'nPredictions': 'nPredictions'}, 'stringSettings': {'title': 'Confusion Matrix Curve'}, 'transform': {'name': 'tableWithLeafColNames'}, 'userQuery': {'queryFields': [{'name': 'runSets', 'args': [{'name': 'runSets', 'value': '${runSets}'}], 'fields': [{'name': 'id', 'fields': []}, {'name': 'name', 'fields': []}, {'name': '_defaultColorIndex', 'fields': []}, {'name': 'summaryTable', 'args': [{'name': 'tableKey', 'value': 'Confusion matrix_table'}], 'fields': []}]}]}}} None
2025-03-15 13:13:49,903 INFO    Thread-16 :21771 [wandb_run.py:_config_callback():1261] config_cb ('_wandb', 'visualize', 'Confusion matrix') {'panel_type': 'Vega2', 'panel_config': {'panelDefId': 'wandb/confusion_matrix/v1', 'fieldSettings': {'Actual': 'Actual', 'Predicted': 'Predicted', 'nPredictions': 'nPredictions'}, 'stringSettings': {'title': 'Confusion Matrix Curve'}, 'transform': {'name': 'tableWithLeafColNames'}, 'userQuery': {'queryFields': [{'name': 'runSets', 'args': [{'name': 'runSets', 'value': '${runSets}'}], 'fields': [{'name': 'id', 'fields': []}, {'name': 'name', 'fields': []}, {'name': '_defaultColorIndex', 'fields': []}, {'name': 'summaryTable', 'args': [{'name': 'tableKey', 'value': 'Confusion matrix_table'}], 'fields': []}]}]}}} None
2025-03-15 13:14:36,994 INFO    Thread-16 :21771 [wandb_run.py:_config_callback():1261] config_cb ('_wandb', 'visualize', 'Confusion matrix') {'panel_type': 'Vega2', 'panel_config': {'panelDefId': 'wandb/confusion_matrix/v1', 'fieldSettings': {'Actual': 'Actual', 'Predicted': 'Predicted', 'nPredictions': 'nPredictions'}, 'stringSettings': {'title': 'Confusion Matrix Curve'}, 'transform': {'name': 'tableWithLeafColNames'}, 'userQuery': {'queryFields': [{'name': 'runSets', 'args': [{'name': 'runSets', 'value': '${runSets}'}], 'fields': [{'name': 'id', 'fields': []}, {'name': 'name', 'fields': []}, {'name': '_defaultColorIndex', 'fields': []}, {'name': 'summaryTable', 'args': [{'name': 'tableKey', 'value': 'Confusion matrix_table'}], 'fields': []}]}]}}} None
2025-03-15 13:15:25,288 INFO    Thread-16 :21771 [wandb_run.py:_config_callback():1261] config_cb ('_wandb', 'visualize', 'Confusion matrix') {'panel_type': 'Vega2', 'panel_config': {'panelDefId': 'wandb/confusion_matrix/v1', 'fieldSettings': {'Actual': 'Actual', 'Predicted': 'Predicted', 'nPredictions': 'nPredictions'}, 'stringSettings': {'title': 'Confusion Matrix Curve'}, 'transform': {'name': 'tableWithLeafColNames'}, 'userQuery': {'queryFields': [{'name': 'runSets', 'args': [{'name': 'runSets', 'value': '${runSets}'}], 'fields': [{'name': 'id', 'fields': []}, {'name': 'name', 'fields': []}, {'name': '_defaultColorIndex', 'fields': []}, {'name': 'summaryTable', 'args': [{'name': 'tableKey', 'value': 'Confusion matrix_table'}], 'fields': []}]}]}}} None
2025-03-15 13:31:12,512 INFO    Thread-16 :21771 [wandb_run.py:_config_callback():1261] config_cb ('_wandb', 'visualize', 'Confusion matrix') {'panel_type': 'Vega2', 'panel_config': {'panelDefId': 'wandb/confusion_matrix/v1', 'fieldSettings': {'Actual': 'Actual', 'Predicted': 'Predicted', 'nPredictions': 'nPredictions'}, 'stringSettings': {'title': 'Confusion Matrix Curve'}, 'transform': {'name': 'tableWithLeafColNames'}, 'userQuery': {'queryFields': [{'name': 'runSets', 'args': [{'name': 'runSets', 'value': '${runSets}'}], 'fields': [{'name': 'id', 'fields': []}, {'name': 'name', 'fields': []}, {'name': '_defaultColorIndex', 'fields': []}, {'name': 'summaryTable', 'args': [{'name': 'tableKey', 'value': 'Confusion matrix_table'}], 'fields': []}]}]}}} None
2025-03-15 13:32:18,171 INFO    Thread-16 :21771 [wandb_run.py:_config_callback():1261] config_cb ('_wandb', 'visualize', 'Confusion matrix') {'panel_type': 'Vega2', 'panel_config': {'panelDefId': 'wandb/confusion_matrix/v1', 'fieldSettings': {'Actual': 'Actual', 'Predicted': 'Predicted', 'nPredictions': 'nPredictions'}, 'stringSettings': {'title': 'Confusion Matrix Curve'}, 'transform': {'name': 'tableWithLeafColNames'}, 'userQuery': {'queryFields': [{'name': 'runSets', 'args': [{'name': 'runSets', 'value': '${runSets}'}], 'fields': [{'name': 'id', 'fields': []}, {'name': 'name', 'fields': []}, {'name': '_defaultColorIndex', 'fields': []}, {'name': 'summaryTable', 'args': [{'name': 'tableKey', 'value': 'Confusion matrix_table'}], 'fields': []}]}]}}} None
2025-03-15 14:46:45,346 INFO    Thread-16 :21771 [wandb_run.py:_config_callback():1261] config_cb ('_wandb', 'visualize', 'Confusion matrix') {'panel_type': 'Vega2', 'panel_config': {'panelDefId': 'wandb/confusion_matrix/v1', 'fieldSettings': {'Actual': 'Actual', 'Predicted': 'Predicted', 'nPredictions': 'nPredictions'}, 'stringSettings': {'title': 'Confusion Matrix Curve'}, 'transform': {'name': 'tableWithLeafColNames'}, 'userQuery': {'queryFields': [{'name': 'runSets', 'args': [{'name': 'runSets', 'value': '${runSets}'}], 'fields': [{'name': 'id', 'fields': []}, {'name': 'name', 'fields': []}, {'name': '_defaultColorIndex', 'fields': []}, {'name': 'summaryTable', 'args': [{'name': 'tableKey', 'value': 'Confusion matrix_table'}], 'fields': []}]}]}}} None
2025-03-15 14:46:47,631 INFO    Thread-3  :21771 [retry.py:__call__():175] Retry attempt failed:
Traceback (most recent call last):
  File "/Users/rudra_sarkar/Documents/CNN_practice/5h_prac/TFODCourse/tfod_new/env/lib/python3.8/site-packages/urllib3/connection.py", line 174, in _new_conn
    conn = connection.create_connection(
  File "/Users/rudra_sarkar/Documents/CNN_practice/5h_prac/TFODCourse/tfod_new/env/lib/python3.8/site-packages/urllib3/util/connection.py", line 72, in create_connection
    for res in socket.getaddrinfo(host, port, family, socket.SOCK_STREAM):
  File "/Users/rudra_sarkar/Documents/CNN_practice/5h_prac/TFODCourse/tfod_new/env/lib/python3.8/socket.py", line 918, in getaddrinfo
    for res in _socket.getaddrinfo(host, port, family, type, proto, flags):
socket.gaierror: [Errno 8] nodename nor servname provided, or not known

During handling of the above exception, another exception occurred:

Traceback (most recent call last):
  File "/Users/rudra_sarkar/Documents/CNN_practice/5h_prac/TFODCourse/tfod_new/env/lib/python3.8/site-packages/urllib3/connectionpool.py", line 703, in urlopen
    httplib_response = self._make_request(
  File "/Users/rudra_sarkar/Documents/CNN_practice/5h_prac/TFODCourse/tfod_new/env/lib/python3.8/site-packages/urllib3/connectionpool.py", line 386, in _make_request
    self._validate_conn(conn)
  File "/Users/rudra_sarkar/Documents/CNN_practice/5h_prac/TFODCourse/tfod_new/env/lib/python3.8/site-packages/urllib3/connectionpool.py", line 1042, in _validate_conn
    conn.connect()
  File "/Users/rudra_sarkar/Documents/CNN_practice/5h_prac/TFODCourse/tfod_new/env/lib/python3.8/site-packages/urllib3/connection.py", line 358, in connect
    self.sock = conn = self._new_conn()
  File "/Users/rudra_sarkar/Documents/CNN_practice/5h_prac/TFODCourse/tfod_new/env/lib/python3.8/site-packages/urllib3/connection.py", line 186, in _new_conn
    raise NewConnectionError(
urllib3.exceptions.NewConnectionError: <urllib3.connection.HTTPSConnection object at 0x154cba5b0>: Failed to establish a new connection: [Errno 8] nodename nor servname provided, or not known

During handling of the above exception, another exception occurred:

Traceback (most recent call last):
  File "/Users/rudra_sarkar/Documents/CNN_practice/5h_prac/TFODCourse/tfod_new/env/lib/python3.8/site-packages/requests/adapters.py", line 489, in send
    resp = conn.urlopen(
  File "/Users/rudra_sarkar/Documents/CNN_practice/5h_prac/TFODCourse/tfod_new/env/lib/python3.8/site-packages/urllib3/connectionpool.py", line 787, in urlopen
    retries = retries.increment(
  File "/Users/rudra_sarkar/Documents/CNN_practice/5h_prac/TFODCourse/tfod_new/env/lib/python3.8/site-packages/urllib3/util/retry.py", line 592, in increment
    raise MaxRetryError(_pool, url, error or ResponseError(cause))
urllib3.exceptions.MaxRetryError: HTTPSConnectionPool(host='api.wandb.ai', port=443): Max retries exceeded with url: /graphql (Caused by NewConnectionError('<urllib3.connection.HTTPSConnection object at 0x154cba5b0>: Failed to establish a new connection: [Errno 8] nodename nor servname provided, or not known'))

During handling of the above exception, another exception occurred:

Traceback (most recent call last):
  File "/Users/rudra_sarkar/Documents/CNN_practice/5h_prac/TFODCourse/tfod_new/env/lib/python3.8/site-packages/wandb/sdk/lib/retry.py", line 134, in __call__
    result = self._call_fn(*args, **kwargs)
  File "/Users/rudra_sarkar/Documents/CNN_practice/5h_prac/TFODCourse/tfod_new/env/lib/python3.8/site-packages/wandb/sdk/internal/internal_api.py", line 398, in execute
    return self.client.execute(*args, **kwargs)  # type: ignore
  File "/Users/rudra_sarkar/Documents/CNN_practice/5h_prac/TFODCourse/tfod_new/env/lib/python3.8/site-packages/wandb/vendor/gql-0.2.0/wandb_gql/client.py", line 52, in execute
    result = self._get_result(document, *args, **kwargs)
  File "/Users/rudra_sarkar/Documents/CNN_practice/5h_prac/TFODCourse/tfod_new/env/lib/python3.8/site-packages/wandb/vendor/gql-0.2.0/wandb_gql/client.py", line 60, in _get_result
    return self.transport.execute(document, *args, **kwargs)
  File "/Users/rudra_sarkar/Documents/CNN_practice/5h_prac/TFODCourse/tfod_new/env/lib/python3.8/site-packages/wandb/sdk/lib/gql_request.py", line 58, in execute
    request = self.session.post(self.url, **post_args)
  File "/Users/rudra_sarkar/Documents/CNN_practice/5h_prac/TFODCourse/tfod_new/env/lib/python3.8/site-packages/requests/sessions.py", line 635, in post
    return self.request("POST", url, data=data, json=json, **kwargs)
  File "/Users/rudra_sarkar/Documents/CNN_practice/5h_prac/TFODCourse/tfod_new/env/lib/python3.8/site-packages/requests/sessions.py", line 587, in request
    resp = self.send(prep, **send_kwargs)
  File "/Users/rudra_sarkar/Documents/CNN_practice/5h_prac/TFODCourse/tfod_new/env/lib/python3.8/site-packages/requests/sessions.py", line 701, in send
    r = adapter.send(request, **kwargs)
  File "/Users/rudra_sarkar/Documents/CNN_practice/5h_prac/TFODCourse/tfod_new/env/lib/python3.8/site-packages/requests/adapters.py", line 565, in send
    raise ConnectionError(e, request=request)
requests.exceptions.ConnectionError: HTTPSConnectionPool(host='api.wandb.ai', port=443): Max retries exceeded with url: /graphql (Caused by NewConnectionError('<urllib3.connection.HTTPSConnection object at 0x154cba5b0>: Failed to establish a new connection: [Errno 8] nodename nor servname provided, or not known'))
2025-03-15 14:46:48,755 INFO    Thread-16 :21771 [retry.py:__call__():175] Retry attempt failed:
Traceback (most recent call last):
  File "/Users/rudra_sarkar/Documents/CNN_practice/5h_prac/TFODCourse/tfod_new/env/lib/python3.8/site-packages/urllib3/connection.py", line 174, in _new_conn
    conn = connection.create_connection(
  File "/Users/rudra_sarkar/Documents/CNN_practice/5h_prac/TFODCourse/tfod_new/env/lib/python3.8/site-packages/urllib3/util/connection.py", line 72, in create_connection
    for res in socket.getaddrinfo(host, port, family, socket.SOCK_STREAM):
  File "/Users/rudra_sarkar/Documents/CNN_practice/5h_prac/TFODCourse/tfod_new/env/lib/python3.8/socket.py", line 918, in getaddrinfo
    for res in _socket.getaddrinfo(host, port, family, type, proto, flags):
socket.gaierror: [Errno 8] nodename nor servname provided, or not known

During handling of the above exception, another exception occurred:

Traceback (most recent call last):
  File "/Users/rudra_sarkar/Documents/CNN_practice/5h_prac/TFODCourse/tfod_new/env/lib/python3.8/site-packages/urllib3/connectionpool.py", line 703, in urlopen
    httplib_response = self._make_request(
  File "/Users/rudra_sarkar/Documents/CNN_practice/5h_prac/TFODCourse/tfod_new/env/lib/python3.8/site-packages/urllib3/connectionpool.py", line 386, in _make_request
    self._validate_conn(conn)
  File "/Users/rudra_sarkar/Documents/CNN_practice/5h_prac/TFODCourse/tfod_new/env/lib/python3.8/site-packages/urllib3/connectionpool.py", line 1042, in _validate_conn
    conn.connect()
  File "/Users/rudra_sarkar/Documents/CNN_practice/5h_prac/TFODCourse/tfod_new/env/lib/python3.8/site-packages/urllib3/connection.py", line 358, in connect
    self.sock = conn = self._new_conn()
  File "/Users/rudra_sarkar/Documents/CNN_practice/5h_prac/TFODCourse/tfod_new/env/lib/python3.8/site-packages/urllib3/connection.py", line 186, in _new_conn
    raise NewConnectionError(
urllib3.exceptions.NewConnectionError: <urllib3.connection.HTTPSConnection object at 0x154cba130>: Failed to establish a new connection: [Errno 8] nodename nor servname provided, or not known

During handling of the above exception, another exception occurred:

Traceback (most recent call last):
  File "/Users/rudra_sarkar/Documents/CNN_practice/5h_prac/TFODCourse/tfod_new/env/lib/python3.8/site-packages/requests/adapters.py", line 489, in send
    resp = conn.urlopen(
  File "/Users/rudra_sarkar/Documents/CNN_practice/5h_prac/TFODCourse/tfod_new/env/lib/python3.8/site-packages/urllib3/connectionpool.py", line 787, in urlopen
    retries = retries.increment(
  File "/Users/rudra_sarkar/Documents/CNN_practice/5h_prac/TFODCourse/tfod_new/env/lib/python3.8/site-packages/urllib3/util/retry.py", line 592, in increment
    raise MaxRetryError(_pool, url, error or ResponseError(cause))
urllib3.exceptions.MaxRetryError: HTTPSConnectionPool(host='api.wandb.ai', port=443): Max retries exceeded with url: /graphql (Caused by NewConnectionError('<urllib3.connection.HTTPSConnection object at 0x154cba130>: Failed to establish a new connection: [Errno 8] nodename nor servname provided, or not known'))

During handling of the above exception, another exception occurred:

Traceback (most recent call last):
  File "/Users/rudra_sarkar/Documents/CNN_practice/5h_prac/TFODCourse/tfod_new/env/lib/python3.8/site-packages/wandb/sdk/lib/retry.py", line 134, in __call__
    result = self._call_fn(*args, **kwargs)
  File "/Users/rudra_sarkar/Documents/CNN_practice/5h_prac/TFODCourse/tfod_new/env/lib/python3.8/site-packages/wandb/apis/public/api.py", line 79, in execute
    return self._client.execute(*args, **kwargs)
  File "/Users/rudra_sarkar/Documents/CNN_practice/5h_prac/TFODCourse/tfod_new/env/lib/python3.8/site-packages/wandb/vendor/gql-0.2.0/wandb_gql/client.py", line 52, in execute
    result = self._get_result(document, *args, **kwargs)
  File "/Users/rudra_sarkar/Documents/CNN_practice/5h_prac/TFODCourse/tfod_new/env/lib/python3.8/site-packages/wandb/vendor/gql-0.2.0/wandb_gql/client.py", line 60, in _get_result
    return self.transport.execute(document, *args, **kwargs)
  File "/Users/rudra_sarkar/Documents/CNN_practice/5h_prac/TFODCourse/tfod_new/env/lib/python3.8/site-packages/wandb/sdk/lib/gql_request.py", line 58, in execute
    request = self.session.post(self.url, **post_args)
  File "/Users/rudra_sarkar/Documents/CNN_practice/5h_prac/TFODCourse/tfod_new/env/lib/python3.8/site-packages/requests/sessions.py", line 635, in post
    return self.request("POST", url, data=data, json=json, **kwargs)
  File "/Users/rudra_sarkar/Documents/CNN_practice/5h_prac/TFODCourse/tfod_new/env/lib/python3.8/site-packages/requests/sessions.py", line 587, in request
    resp = self.send(prep, **send_kwargs)
  File "/Users/rudra_sarkar/Documents/CNN_practice/5h_prac/TFODCourse/tfod_new/env/lib/python3.8/site-packages/requests/sessions.py", line 701, in send
    r = adapter.send(request, **kwargs)
  File "/Users/rudra_sarkar/Documents/CNN_practice/5h_prac/TFODCourse/tfod_new/env/lib/python3.8/site-packages/requests/adapters.py", line 565, in send
    raise ConnectionError(e, request=request)
requests.exceptions.ConnectionError: HTTPSConnectionPool(host='api.wandb.ai', port=443): Max retries exceeded with url: /graphql (Caused by NewConnectionError('<urllib3.connection.HTTPSConnection object at 0x154cba130>: Failed to establish a new connection: [Errno 8] nodename nor servname provided, or not known'))
2025-03-15 15:32:59,826 INFO    Thread-16 :21771 [wandb_run.py:_config_callback():1261] config_cb ('_wandb', 'visualize', 'Confusion matrix') {'panel_type': 'Vega2', 'panel_config': {'panelDefId': 'wandb/confusion_matrix/v1', 'fieldSettings': {'Actual': 'Actual', 'Predicted': 'Predicted', 'nPredictions': 'nPredictions'}, 'stringSettings': {'title': 'Confusion Matrix Curve'}, 'transform': {'name': 'tableWithLeafColNames'}, 'userQuery': {'queryFields': [{'name': 'runSets', 'args': [{'name': 'runSets', 'value': '${runSets}'}], 'fields': [{'name': 'id', 'fields': []}, {'name': 'name', 'fields': []}, {'name': '_defaultColorIndex', 'fields': []}, {'name': 'summaryTable', 'args': [{'name': 'tableKey', 'value': 'Confusion matrix_table'}], 'fields': []}]}]}}} None
2025-03-15 15:34:08,295 INFO    Thread-16 :21771 [wandb_run.py:_config_callback():1261] config_cb ('_wandb', 'visualize', 'Confusion matrix') {'panel_type': 'Vega2', 'panel_config': {'panelDefId': 'wandb/confusion_matrix/v1', 'fieldSettings': {'Actual': 'Actual', 'Predicted': 'Predicted', 'nPredictions': 'nPredictions'}, 'stringSettings': {'title': 'Confusion Matrix Curve'}, 'transform': {'name': 'tableWithLeafColNames'}, 'userQuery': {'queryFields': [{'name': 'runSets', 'args': [{'name': 'runSets', 'value': '${runSets}'}], 'fields': [{'name': 'id', 'fields': []}, {'name': 'name', 'fields': []}, {'name': '_defaultColorIndex', 'fields': []}, {'name': 'summaryTable', 'args': [{'name': 'tableKey', 'value': 'Confusion matrix_table'}], 'fields': []}]}]}}} None
2025-03-15 15:35:11,202 INFO    Thread-16 :21771 [wandb_run.py:_config_callback():1261] config_cb ('_wandb', 'visualize', 'Confusion matrix') {'panel_type': 'Vega2', 'panel_config': {'panelDefId': 'wandb/confusion_matrix/v1', 'fieldSettings': {'Actual': 'Actual', 'Predicted': 'Predicted', 'nPredictions': 'nPredictions'}, 'stringSettings': {'title': 'Confusion Matrix Curve'}, 'transform': {'name': 'tableWithLeafColNames'}, 'userQuery': {'queryFields': [{'name': 'runSets', 'args': [{'name': 'runSets', 'value': '${runSets}'}], 'fields': [{'name': 'id', 'fields': []}, {'name': 'name', 'fields': []}, {'name': '_defaultColorIndex', 'fields': []}, {'name': 'summaryTable', 'args': [{'name': 'tableKey', 'value': 'Confusion matrix_table'}], 'fields': []}]}]}}} None
2025-03-15 15:37:21,510 INFO    Thread-16 :21771 [wandb_run.py:_config_callback():1261] config_cb ('_wandb', 'visualize', 'Confusion matrix') {'panel_type': 'Vega2', 'panel_config': {'panelDefId': 'wandb/confusion_matrix/v1', 'fieldSettings': {'Actual': 'Actual', 'Predicted': 'Predicted', 'nPredictions': 'nPredictions'}, 'stringSettings': {'title': 'Confusion Matrix Curve'}, 'transform': {'name': 'tableWithLeafColNames'}, 'userQuery': {'queryFields': [{'name': 'runSets', 'args': [{'name': 'runSets', 'value': '${runSets}'}], 'fields': [{'name': 'id', 'fields': []}, {'name': 'name', 'fields': []}, {'name': '_defaultColorIndex', 'fields': []}, {'name': 'summaryTable', 'args': [{'name': 'tableKey', 'value': 'Confusion matrix_table'}], 'fields': []}]}]}}} None
2025-03-15 15:41:58,875 INFO    Thread-16 :21771 [wandb_run.py:_config_callback():1261] config_cb ('_wandb', 'visualize', 'Confusion matrix') {'panel_type': 'Vega2', 'panel_config': {'panelDefId': 'wandb/confusion_matrix/v1', 'fieldSettings': {'Actual': 'Actual', 'Predicted': 'Predicted', 'nPredictions': 'nPredictions'}, 'stringSettings': {'title': 'Confusion Matrix Curve'}, 'transform': {'name': 'tableWithLeafColNames'}, 'userQuery': {'queryFields': [{'name': 'runSets', 'args': [{'name': 'runSets', 'value': '${runSets}'}], 'fields': [{'name': 'id', 'fields': []}, {'name': 'name', 'fields': []}, {'name': '_defaultColorIndex', 'fields': []}, {'name': 'summaryTable', 'args': [{'name': 'tableKey', 'value': 'Confusion matrix_table'}], 'fields': []}]}]}}} None
2025-03-15 15:44:12,931 INFO    Thread-16 :21771 [wandb_run.py:_config_callback():1261] config_cb ('_wandb', 'visualize', 'Confusion matrix') {'panel_type': 'Vega2', 'panel_config': {'panelDefId': 'wandb/confusion_matrix/v1', 'fieldSettings': {'Actual': 'Actual', 'Predicted': 'Predicted', 'nPredictions': 'nPredictions'}, 'stringSettings': {'title': 'Confusion Matrix Curve'}, 'transform': {'name': 'tableWithLeafColNames'}, 'userQuery': {'queryFields': [{'name': 'runSets', 'args': [{'name': 'runSets', 'value': '${runSets}'}], 'fields': [{'name': 'id', 'fields': []}, {'name': 'name', 'fields': []}, {'name': '_defaultColorIndex', 'fields': []}, {'name': 'summaryTable', 'args': [{'name': 'tableKey', 'value': 'Confusion matrix_table'}], 'fields': []}]}]}}} None
2025-03-15 15:46:21,790 INFO    Thread-16 :21771 [wandb_run.py:_config_callback():1261] config_cb ('_wandb', 'visualize', 'Confusion matrix') {'panel_type': 'Vega2', 'panel_config': {'panelDefId': 'wandb/confusion_matrix/v1', 'fieldSettings': {'Actual': 'Actual', 'Predicted': 'Predicted', 'nPredictions': 'nPredictions'}, 'stringSettings': {'title': 'Confusion Matrix Curve'}, 'transform': {'name': 'tableWithLeafColNames'}, 'userQuery': {'queryFields': [{'name': 'runSets', 'args': [{'name': 'runSets', 'value': '${runSets}'}], 'fields': [{'name': 'id', 'fields': []}, {'name': 'name', 'fields': []}, {'name': '_defaultColorIndex', 'fields': []}, {'name': 'summaryTable', 'args': [{'name': 'tableKey', 'value': 'Confusion matrix_table'}], 'fields': []}]}]}}} None
2025-03-15 15:50:24,070 INFO    Thread-16 :21771 [retry.py:__call__():175] Retry attempt failed:
Traceback (most recent call last):
  File "/Users/rudra_sarkar/Documents/CNN_practice/5h_prac/TFODCourse/tfod_new/env/lib/python3.8/site-packages/urllib3/connection.py", line 174, in _new_conn
    conn = connection.create_connection(
  File "/Users/rudra_sarkar/Documents/CNN_practice/5h_prac/TFODCourse/tfod_new/env/lib/python3.8/site-packages/urllib3/util/connection.py", line 72, in create_connection
    for res in socket.getaddrinfo(host, port, family, socket.SOCK_STREAM):
  File "/Users/rudra_sarkar/Documents/CNN_practice/5h_prac/TFODCourse/tfod_new/env/lib/python3.8/socket.py", line 918, in getaddrinfo
    for res in _socket.getaddrinfo(host, port, family, type, proto, flags):
socket.gaierror: [Errno 8] nodename nor servname provided, or not known

During handling of the above exception, another exception occurred:

Traceback (most recent call last):
  File "/Users/rudra_sarkar/Documents/CNN_practice/5h_prac/TFODCourse/tfod_new/env/lib/python3.8/site-packages/urllib3/connectionpool.py", line 703, in urlopen
    httplib_response = self._make_request(
  File "/Users/rudra_sarkar/Documents/CNN_practice/5h_prac/TFODCourse/tfod_new/env/lib/python3.8/site-packages/urllib3/connectionpool.py", line 386, in _make_request
    self._validate_conn(conn)
  File "/Users/rudra_sarkar/Documents/CNN_practice/5h_prac/TFODCourse/tfod_new/env/lib/python3.8/site-packages/urllib3/connectionpool.py", line 1042, in _validate_conn
    conn.connect()
  File "/Users/rudra_sarkar/Documents/CNN_practice/5h_prac/TFODCourse/tfod_new/env/lib/python3.8/site-packages/urllib3/connection.py", line 358, in connect
    self.sock = conn = self._new_conn()
  File "/Users/rudra_sarkar/Documents/CNN_practice/5h_prac/TFODCourse/tfod_new/env/lib/python3.8/site-packages/urllib3/connection.py", line 186, in _new_conn
    raise NewConnectionError(
urllib3.exceptions.NewConnectionError: <urllib3.connection.HTTPSConnection object at 0x168c4a820>: Failed to establish a new connection: [Errno 8] nodename nor servname provided, or not known

During handling of the above exception, another exception occurred:

Traceback (most recent call last):
  File "/Users/rudra_sarkar/Documents/CNN_practice/5h_prac/TFODCourse/tfod_new/env/lib/python3.8/site-packages/requests/adapters.py", line 489, in send
    resp = conn.urlopen(
  File "/Users/rudra_sarkar/Documents/CNN_practice/5h_prac/TFODCourse/tfod_new/env/lib/python3.8/site-packages/urllib3/connectionpool.py", line 787, in urlopen
    retries = retries.increment(
  File "/Users/rudra_sarkar/Documents/CNN_practice/5h_prac/TFODCourse/tfod_new/env/lib/python3.8/site-packages/urllib3/util/retry.py", line 592, in increment
    raise MaxRetryError(_pool, url, error or ResponseError(cause))
urllib3.exceptions.MaxRetryError: HTTPSConnectionPool(host='api.wandb.ai', port=443): Max retries exceeded with url: /graphql (Caused by NewConnectionError('<urllib3.connection.HTTPSConnection object at 0x168c4a820>: Failed to establish a new connection: [Errno 8] nodename nor servname provided, or not known'))

During handling of the above exception, another exception occurred:

Traceback (most recent call last):
  File "/Users/rudra_sarkar/Documents/CNN_practice/5h_prac/TFODCourse/tfod_new/env/lib/python3.8/site-packages/wandb/sdk/lib/retry.py", line 134, in __call__
    result = self._call_fn(*args, **kwargs)
  File "/Users/rudra_sarkar/Documents/CNN_practice/5h_prac/TFODCourse/tfod_new/env/lib/python3.8/site-packages/wandb/apis/public/api.py", line 79, in execute
    return self._client.execute(*args, **kwargs)
  File "/Users/rudra_sarkar/Documents/CNN_practice/5h_prac/TFODCourse/tfod_new/env/lib/python3.8/site-packages/wandb/vendor/gql-0.2.0/wandb_gql/client.py", line 52, in execute
    result = self._get_result(document, *args, **kwargs)
  File "/Users/rudra_sarkar/Documents/CNN_practice/5h_prac/TFODCourse/tfod_new/env/lib/python3.8/site-packages/wandb/vendor/gql-0.2.0/wandb_gql/client.py", line 60, in _get_result
    return self.transport.execute(document, *args, **kwargs)
  File "/Users/rudra_sarkar/Documents/CNN_practice/5h_prac/TFODCourse/tfod_new/env/lib/python3.8/site-packages/wandb/sdk/lib/gql_request.py", line 58, in execute
    request = self.session.post(self.url, **post_args)
  File "/Users/rudra_sarkar/Documents/CNN_practice/5h_prac/TFODCourse/tfod_new/env/lib/python3.8/site-packages/requests/sessions.py", line 635, in post
    return self.request("POST", url, data=data, json=json, **kwargs)
  File "/Users/rudra_sarkar/Documents/CNN_practice/5h_prac/TFODCourse/tfod_new/env/lib/python3.8/site-packages/requests/sessions.py", line 587, in request
    resp = self.send(prep, **send_kwargs)
  File "/Users/rudra_sarkar/Documents/CNN_practice/5h_prac/TFODCourse/tfod_new/env/lib/python3.8/site-packages/requests/sessions.py", line 701, in send
    r = adapter.send(request, **kwargs)
  File "/Users/rudra_sarkar/Documents/CNN_practice/5h_prac/TFODCourse/tfod_new/env/lib/python3.8/site-packages/requests/adapters.py", line 565, in send
    raise ConnectionError(e, request=request)
requests.exceptions.ConnectionError: HTTPSConnectionPool(host='api.wandb.ai', port=443): Max retries exceeded with url: /graphql (Caused by NewConnectionError('<urllib3.connection.HTTPSConnection object at 0x168c4a820>: Failed to establish a new connection: [Errno 8] nodename nor servname provided, or not known'))
2025-03-15 15:54:51,900 INFO    Thread-16 :21771 [wandb_run.py:_config_callback():1261] config_cb ('_wandb', 'visualize', 'Confusion matrix') {'panel_type': 'Vega2', 'panel_config': {'panelDefId': 'wandb/confusion_matrix/v1', 'fieldSettings': {'Actual': 'Actual', 'Predicted': 'Predicted', 'nPredictions': 'nPredictions'}, 'stringSettings': {'title': 'Confusion Matrix Curve'}, 'transform': {'name': 'tableWithLeafColNames'}, 'userQuery': {'queryFields': [{'name': 'runSets', 'args': [{'name': 'runSets', 'value': '${runSets}'}], 'fields': [{'name': 'id', 'fields': []}, {'name': 'name', 'fields': []}, {'name': '_defaultColorIndex', 'fields': []}, {'name': 'summaryTable', 'args': [{'name': 'tableKey', 'value': 'Confusion matrix_table'}], 'fields': []}]}]}}} None
2025-03-15 15:54:55,404 INFO    Thread-16 :21771 [retry.py:__call__():175] Retry attempt failed:
Traceback (most recent call last):
  File "/Users/rudra_sarkar/Documents/CNN_practice/5h_prac/TFODCourse/tfod_new/env/lib/python3.8/site-packages/urllib3/connection.py", line 174, in _new_conn
    conn = connection.create_connection(
  File "/Users/rudra_sarkar/Documents/CNN_practice/5h_prac/TFODCourse/tfod_new/env/lib/python3.8/site-packages/urllib3/util/connection.py", line 72, in create_connection
    for res in socket.getaddrinfo(host, port, family, socket.SOCK_STREAM):
  File "/Users/rudra_sarkar/Documents/CNN_practice/5h_prac/TFODCourse/tfod_new/env/lib/python3.8/socket.py", line 918, in getaddrinfo
    for res in _socket.getaddrinfo(host, port, family, type, proto, flags):
socket.gaierror: [Errno 8] nodename nor servname provided, or not known

During handling of the above exception, another exception occurred:

Traceback (most recent call last):
  File "/Users/rudra_sarkar/Documents/CNN_practice/5h_prac/TFODCourse/tfod_new/env/lib/python3.8/site-packages/urllib3/connectionpool.py", line 703, in urlopen
    httplib_response = self._make_request(
  File "/Users/rudra_sarkar/Documents/CNN_practice/5h_prac/TFODCourse/tfod_new/env/lib/python3.8/site-packages/urllib3/connectionpool.py", line 386, in _make_request
    self._validate_conn(conn)
  File "/Users/rudra_sarkar/Documents/CNN_practice/5h_prac/TFODCourse/tfod_new/env/lib/python3.8/site-packages/urllib3/connectionpool.py", line 1042, in _validate_conn
    conn.connect()
  File "/Users/rudra_sarkar/Documents/CNN_practice/5h_prac/TFODCourse/tfod_new/env/lib/python3.8/site-packages/urllib3/connection.py", line 358, in connect
    self.sock = conn = self._new_conn()
  File "/Users/rudra_sarkar/Documents/CNN_practice/5h_prac/TFODCourse/tfod_new/env/lib/python3.8/site-packages/urllib3/connection.py", line 186, in _new_conn
    raise NewConnectionError(
urllib3.exceptions.NewConnectionError: <urllib3.connection.HTTPSConnection object at 0x156df7cd0>: Failed to establish a new connection: [Errno 8] nodename nor servname provided, or not known

During handling of the above exception, another exception occurred:

Traceback (most recent call last):
  File "/Users/rudra_sarkar/Documents/CNN_practice/5h_prac/TFODCourse/tfod_new/env/lib/python3.8/site-packages/requests/adapters.py", line 489, in send
    resp = conn.urlopen(
  File "/Users/rudra_sarkar/Documents/CNN_practice/5h_prac/TFODCourse/tfod_new/env/lib/python3.8/site-packages/urllib3/connectionpool.py", line 787, in urlopen
    retries = retries.increment(
  File "/Users/rudra_sarkar/Documents/CNN_practice/5h_prac/TFODCourse/tfod_new/env/lib/python3.8/site-packages/urllib3/util/retry.py", line 592, in increment
    raise MaxRetryError(_pool, url, error or ResponseError(cause))
urllib3.exceptions.MaxRetryError: HTTPSConnectionPool(host='api.wandb.ai', port=443): Max retries exceeded with url: /graphql (Caused by NewConnectionError('<urllib3.connection.HTTPSConnection object at 0x156df7cd0>: Failed to establish a new connection: [Errno 8] nodename nor servname provided, or not known'))

During handling of the above exception, another exception occurred:

Traceback (most recent call last):
  File "/Users/rudra_sarkar/Documents/CNN_practice/5h_prac/TFODCourse/tfod_new/env/lib/python3.8/site-packages/wandb/sdk/lib/retry.py", line 134, in __call__
    result = self._call_fn(*args, **kwargs)
  File "/Users/rudra_sarkar/Documents/CNN_practice/5h_prac/TFODCourse/tfod_new/env/lib/python3.8/site-packages/wandb/apis/public/api.py", line 79, in execute
    return self._client.execute(*args, **kwargs)
  File "/Users/rudra_sarkar/Documents/CNN_practice/5h_prac/TFODCourse/tfod_new/env/lib/python3.8/site-packages/wandb/vendor/gql-0.2.0/wandb_gql/client.py", line 52, in execute
    result = self._get_result(document, *args, **kwargs)
  File "/Users/rudra_sarkar/Documents/CNN_practice/5h_prac/TFODCourse/tfod_new/env/lib/python3.8/site-packages/wandb/vendor/gql-0.2.0/wandb_gql/client.py", line 60, in _get_result
    return self.transport.execute(document, *args, **kwargs)
  File "/Users/rudra_sarkar/Documents/CNN_practice/5h_prac/TFODCourse/tfod_new/env/lib/python3.8/site-packages/wandb/sdk/lib/gql_request.py", line 58, in execute
    request = self.session.post(self.url, **post_args)
  File "/Users/rudra_sarkar/Documents/CNN_practice/5h_prac/TFODCourse/tfod_new/env/lib/python3.8/site-packages/requests/sessions.py", line 635, in post
    return self.request("POST", url, data=data, json=json, **kwargs)
  File "/Users/rudra_sarkar/Documents/CNN_practice/5h_prac/TFODCourse/tfod_new/env/lib/python3.8/site-packages/requests/sessions.py", line 587, in request
    resp = self.send(prep, **send_kwargs)
  File "/Users/rudra_sarkar/Documents/CNN_practice/5h_prac/TFODCourse/tfod_new/env/lib/python3.8/site-packages/requests/sessions.py", line 701, in send
    r = adapter.send(request, **kwargs)
  File "/Users/rudra_sarkar/Documents/CNN_practice/5h_prac/TFODCourse/tfod_new/env/lib/python3.8/site-packages/requests/adapters.py", line 565, in send
    raise ConnectionError(e, request=request)
requests.exceptions.ConnectionError: HTTPSConnectionPool(host='api.wandb.ai', port=443): Max retries exceeded with url: /graphql (Caused by NewConnectionError('<urllib3.connection.HTTPSConnection object at 0x156df7cd0>: Failed to establish a new connection: [Errno 8] nodename nor servname provided, or not known'))
2025-03-15 15:55:31,812 INFO    Thread-16 :21771 [retry.py:__call__():175] Retry attempt failed:
Traceback (most recent call last):
  File "/Users/rudra_sarkar/Documents/CNN_practice/5h_prac/TFODCourse/tfod_new/env/lib/python3.8/site-packages/urllib3/connection.py", line 174, in _new_conn
    conn = connection.create_connection(
  File "/Users/rudra_sarkar/Documents/CNN_practice/5h_prac/TFODCourse/tfod_new/env/lib/python3.8/site-packages/urllib3/util/connection.py", line 72, in create_connection
    for res in socket.getaddrinfo(host, port, family, socket.SOCK_STREAM):
  File "/Users/rudra_sarkar/Documents/CNN_practice/5h_prac/TFODCourse/tfod_new/env/lib/python3.8/socket.py", line 918, in getaddrinfo
    for res in _socket.getaddrinfo(host, port, family, type, proto, flags):
socket.gaierror: [Errno 8] nodename nor servname provided, or not known

During handling of the above exception, another exception occurred:

Traceback (most recent call last):
  File "/Users/rudra_sarkar/Documents/CNN_practice/5h_prac/TFODCourse/tfod_new/env/lib/python3.8/site-packages/urllib3/connectionpool.py", line 703, in urlopen
    httplib_response = self._make_request(
  File "/Users/rudra_sarkar/Documents/CNN_practice/5h_prac/TFODCourse/tfod_new/env/lib/python3.8/site-packages/urllib3/connectionpool.py", line 386, in _make_request
    self._validate_conn(conn)
  File "/Users/rudra_sarkar/Documents/CNN_practice/5h_prac/TFODCourse/tfod_new/env/lib/python3.8/site-packages/urllib3/connectionpool.py", line 1042, in _validate_conn
    conn.connect()
  File "/Users/rudra_sarkar/Documents/CNN_practice/5h_prac/TFODCourse/tfod_new/env/lib/python3.8/site-packages/urllib3/connection.py", line 358, in connect
    self.sock = conn = self._new_conn()
  File "/Users/rudra_sarkar/Documents/CNN_practice/5h_prac/TFODCourse/tfod_new/env/lib/python3.8/site-packages/urllib3/connection.py", line 186, in _new_conn
    raise NewConnectionError(
urllib3.exceptions.NewConnectionError: <urllib3.connection.HTTPSConnection object at 0x156dfac40>: Failed to establish a new connection: [Errno 8] nodename nor servname provided, or not known

During handling of the above exception, another exception occurred:

Traceback (most recent call last):
  File "/Users/rudra_sarkar/Documents/CNN_practice/5h_prac/TFODCourse/tfod_new/env/lib/python3.8/site-packages/requests/adapters.py", line 489, in send
    resp = conn.urlopen(
  File "/Users/rudra_sarkar/Documents/CNN_practice/5h_prac/TFODCourse/tfod_new/env/lib/python3.8/site-packages/urllib3/connectionpool.py", line 787, in urlopen
    retries = retries.increment(
  File "/Users/rudra_sarkar/Documents/CNN_practice/5h_prac/TFODCourse/tfod_new/env/lib/python3.8/site-packages/urllib3/util/retry.py", line 592, in increment
    raise MaxRetryError(_pool, url, error or ResponseError(cause))
urllib3.exceptions.MaxRetryError: HTTPSConnectionPool(host='api.wandb.ai', port=443): Max retries exceeded with url: /graphql (Caused by NewConnectionError('<urllib3.connection.HTTPSConnection object at 0x156dfac40>: Failed to establish a new connection: [Errno 8] nodename nor servname provided, or not known'))

During handling of the above exception, another exception occurred:

Traceback (most recent call last):
  File "/Users/rudra_sarkar/Documents/CNN_practice/5h_prac/TFODCourse/tfod_new/env/lib/python3.8/site-packages/wandb/sdk/lib/retry.py", line 134, in __call__
    result = self._call_fn(*args, **kwargs)
  File "/Users/rudra_sarkar/Documents/CNN_practice/5h_prac/TFODCourse/tfod_new/env/lib/python3.8/site-packages/wandb/apis/public/api.py", line 79, in execute
    return self._client.execute(*args, **kwargs)
  File "/Users/rudra_sarkar/Documents/CNN_practice/5h_prac/TFODCourse/tfod_new/env/lib/python3.8/site-packages/wandb/vendor/gql-0.2.0/wandb_gql/client.py", line 52, in execute
    result = self._get_result(document, *args, **kwargs)
  File "/Users/rudra_sarkar/Documents/CNN_practice/5h_prac/TFODCourse/tfod_new/env/lib/python3.8/site-packages/wandb/vendor/gql-0.2.0/wandb_gql/client.py", line 60, in _get_result
    return self.transport.execute(document, *args, **kwargs)
  File "/Users/rudra_sarkar/Documents/CNN_practice/5h_prac/TFODCourse/tfod_new/env/lib/python3.8/site-packages/wandb/sdk/lib/gql_request.py", line 58, in execute
    request = self.session.post(self.url, **post_args)
  File "/Users/rudra_sarkar/Documents/CNN_practice/5h_prac/TFODCourse/tfod_new/env/lib/python3.8/site-packages/requests/sessions.py", line 635, in post
    return self.request("POST", url, data=data, json=json, **kwargs)
  File "/Users/rudra_sarkar/Documents/CNN_practice/5h_prac/TFODCourse/tfod_new/env/lib/python3.8/site-packages/requests/sessions.py", line 587, in request
    resp = self.send(prep, **send_kwargs)
  File "/Users/rudra_sarkar/Documents/CNN_practice/5h_prac/TFODCourse/tfod_new/env/lib/python3.8/site-packages/requests/sessions.py", line 701, in send
    r = adapter.send(request, **kwargs)
  File "/Users/rudra_sarkar/Documents/CNN_practice/5h_prac/TFODCourse/tfod_new/env/lib/python3.8/site-packages/requests/adapters.py", line 565, in send
    raise ConnectionError(e, request=request)
requests.exceptions.ConnectionError: HTTPSConnectionPool(host='api.wandb.ai', port=443): Max retries exceeded with url: /graphql (Caused by NewConnectionError('<urllib3.connection.HTTPSConnection object at 0x156dfac40>: Failed to establish a new connection: [Errno 8] nodename nor servname provided, or not known'))
2025-03-15 15:57:13,404 INFO    Thread-16 :21771 [wandb_run.py:_config_callback():1261] config_cb ('_wandb', 'visualize', 'Confusion matrix') {'panel_type': 'Vega2', 'panel_config': {'panelDefId': 'wandb/confusion_matrix/v1', 'fieldSettings': {'Actual': 'Actual', 'Predicted': 'Predicted', 'nPredictions': 'nPredictions'}, 'stringSettings': {'title': 'Confusion Matrix Curve'}, 'transform': {'name': 'tableWithLeafColNames'}, 'userQuery': {'queryFields': [{'name': 'runSets', 'args': [{'name': 'runSets', 'value': '${runSets}'}], 'fields': [{'name': 'id', 'fields': []}, {'name': 'name', 'fields': []}, {'name': '_defaultColorIndex', 'fields': []}, {'name': 'summaryTable', 'args': [{'name': 'tableKey', 'value': 'Confusion matrix_table'}], 'fields': []}]}]}}} None
2025-03-15 15:58:30,625 INFO    Thread-16 :21771 [retry.py:__call__():175] Retry attempt failed:
Traceback (most recent call last):
  File "/Users/rudra_sarkar/Documents/CNN_practice/5h_prac/TFODCourse/tfod_new/env/lib/python3.8/site-packages/urllib3/connection.py", line 174, in _new_conn
    conn = connection.create_connection(
  File "/Users/rudra_sarkar/Documents/CNN_practice/5h_prac/TFODCourse/tfod_new/env/lib/python3.8/site-packages/urllib3/util/connection.py", line 72, in create_connection
    for res in socket.getaddrinfo(host, port, family, socket.SOCK_STREAM):
  File "/Users/rudra_sarkar/Documents/CNN_practice/5h_prac/TFODCourse/tfod_new/env/lib/python3.8/socket.py", line 918, in getaddrinfo
    for res in _socket.getaddrinfo(host, port, family, type, proto, flags):
socket.gaierror: [Errno 8] nodename nor servname provided, or not known

During handling of the above exception, another exception occurred:

Traceback (most recent call last):
  File "/Users/rudra_sarkar/Documents/CNN_practice/5h_prac/TFODCourse/tfod_new/env/lib/python3.8/site-packages/urllib3/connectionpool.py", line 703, in urlopen
    httplib_response = self._make_request(
  File "/Users/rudra_sarkar/Documents/CNN_practice/5h_prac/TFODCourse/tfod_new/env/lib/python3.8/site-packages/urllib3/connectionpool.py", line 386, in _make_request
    self._validate_conn(conn)
  File "/Users/rudra_sarkar/Documents/CNN_practice/5h_prac/TFODCourse/tfod_new/env/lib/python3.8/site-packages/urllib3/connectionpool.py", line 1042, in _validate_conn
    conn.connect()
  File "/Users/rudra_sarkar/Documents/CNN_practice/5h_prac/TFODCourse/tfod_new/env/lib/python3.8/site-packages/urllib3/connection.py", line 358, in connect
    self.sock = conn = self._new_conn()
  File "/Users/rudra_sarkar/Documents/CNN_practice/5h_prac/TFODCourse/tfod_new/env/lib/python3.8/site-packages/urllib3/connection.py", line 186, in _new_conn
    raise NewConnectionError(
urllib3.exceptions.NewConnectionError: <urllib3.connection.HTTPSConnection object at 0x157e51100>: Failed to establish a new connection: [Errno 8] nodename nor servname provided, or not known

During handling of the above exception, another exception occurred:

Traceback (most recent call last):
  File "/Users/rudra_sarkar/Documents/CNN_practice/5h_prac/TFODCourse/tfod_new/env/lib/python3.8/site-packages/requests/adapters.py", line 489, in send
    resp = conn.urlopen(
  File "/Users/rudra_sarkar/Documents/CNN_practice/5h_prac/TFODCourse/tfod_new/env/lib/python3.8/site-packages/urllib3/connectionpool.py", line 787, in urlopen
    retries = retries.increment(
  File "/Users/rudra_sarkar/Documents/CNN_practice/5h_prac/TFODCourse/tfod_new/env/lib/python3.8/site-packages/urllib3/util/retry.py", line 592, in increment
    raise MaxRetryError(_pool, url, error or ResponseError(cause))
urllib3.exceptions.MaxRetryError: HTTPSConnectionPool(host='api.wandb.ai', port=443): Max retries exceeded with url: /graphql (Caused by NewConnectionError('<urllib3.connection.HTTPSConnection object at 0x157e51100>: Failed to establish a new connection: [Errno 8] nodename nor servname provided, or not known'))

During handling of the above exception, another exception occurred:

Traceback (most recent call last):
  File "/Users/rudra_sarkar/Documents/CNN_practice/5h_prac/TFODCourse/tfod_new/env/lib/python3.8/site-packages/wandb/sdk/lib/retry.py", line 134, in __call__
    result = self._call_fn(*args, **kwargs)
  File "/Users/rudra_sarkar/Documents/CNN_practice/5h_prac/TFODCourse/tfod_new/env/lib/python3.8/site-packages/wandb/apis/public/api.py", line 79, in execute
    return self._client.execute(*args, **kwargs)
  File "/Users/rudra_sarkar/Documents/CNN_practice/5h_prac/TFODCourse/tfod_new/env/lib/python3.8/site-packages/wandb/vendor/gql-0.2.0/wandb_gql/client.py", line 52, in execute
    result = self._get_result(document, *args, **kwargs)
  File "/Users/rudra_sarkar/Documents/CNN_practice/5h_prac/TFODCourse/tfod_new/env/lib/python3.8/site-packages/wandb/vendor/gql-0.2.0/wandb_gql/client.py", line 60, in _get_result
    return self.transport.execute(document, *args, **kwargs)
  File "/Users/rudra_sarkar/Documents/CNN_practice/5h_prac/TFODCourse/tfod_new/env/lib/python3.8/site-packages/wandb/sdk/lib/gql_request.py", line 58, in execute
    request = self.session.post(self.url, **post_args)
  File "/Users/rudra_sarkar/Documents/CNN_practice/5h_prac/TFODCourse/tfod_new/env/lib/python3.8/site-packages/requests/sessions.py", line 635, in post
    return self.request("POST", url, data=data, json=json, **kwargs)
  File "/Users/rudra_sarkar/Documents/CNN_practice/5h_prac/TFODCourse/tfod_new/env/lib/python3.8/site-packages/requests/sessions.py", line 587, in request
    resp = self.send(prep, **send_kwargs)
  File "/Users/rudra_sarkar/Documents/CNN_practice/5h_prac/TFODCourse/tfod_new/env/lib/python3.8/site-packages/requests/sessions.py", line 701, in send
    r = adapter.send(request, **kwargs)
  File "/Users/rudra_sarkar/Documents/CNN_practice/5h_prac/TFODCourse/tfod_new/env/lib/python3.8/site-packages/requests/adapters.py", line 565, in send
    raise ConnectionError(e, request=request)
requests.exceptions.ConnectionError: HTTPSConnectionPool(host='api.wandb.ai', port=443): Max retries exceeded with url: /graphql (Caused by NewConnectionError('<urllib3.connection.HTTPSConnection object at 0x157e51100>: Failed to establish a new connection: [Errno 8] nodename nor servname provided, or not known'))
2025-03-15 16:04:28,443 INFO    Thread-16 :21771 [wandb_run.py:_config_callback():1261] config_cb ('_wandb', 'visualize', 'Confusion matrix') {'panel_type': 'Vega2', 'panel_config': {'panelDefId': 'wandb/confusion_matrix/v1', 'fieldSettings': {'Actual': 'Actual', 'Predicted': 'Predicted', 'nPredictions': 'nPredictions'}, 'stringSettings': {'title': 'Confusion Matrix Curve'}, 'transform': {'name': 'tableWithLeafColNames'}, 'userQuery': {'queryFields': [{'name': 'runSets', 'args': [{'name': 'runSets', 'value': '${runSets}'}], 'fields': [{'name': 'id', 'fields': []}, {'name': 'name', 'fields': []}, {'name': '_defaultColorIndex', 'fields': []}, {'name': 'summaryTable', 'args': [{'name': 'tableKey', 'value': 'Confusion matrix_table'}], 'fields': []}]}]}}} None
2025-03-15 16:04:35,380 INFO    Thread-16 :21771 [retry.py:__call__():175] Retry attempt failed:
Traceback (most recent call last):
  File "/Users/rudra_sarkar/Documents/CNN_practice/5h_prac/TFODCourse/tfod_new/env/lib/python3.8/site-packages/urllib3/connection.py", line 174, in _new_conn
    conn = connection.create_connection(
  File "/Users/rudra_sarkar/Documents/CNN_practice/5h_prac/TFODCourse/tfod_new/env/lib/python3.8/site-packages/urllib3/util/connection.py", line 72, in create_connection
    for res in socket.getaddrinfo(host, port, family, socket.SOCK_STREAM):
  File "/Users/rudra_sarkar/Documents/CNN_practice/5h_prac/TFODCourse/tfod_new/env/lib/python3.8/socket.py", line 918, in getaddrinfo
    for res in _socket.getaddrinfo(host, port, family, type, proto, flags):
socket.gaierror: [Errno 8] nodename nor servname provided, or not known

During handling of the above exception, another exception occurred:

Traceback (most recent call last):
  File "/Users/rudra_sarkar/Documents/CNN_practice/5h_prac/TFODCourse/tfod_new/env/lib/python3.8/site-packages/urllib3/connectionpool.py", line 703, in urlopen
    httplib_response = self._make_request(
  File "/Users/rudra_sarkar/Documents/CNN_practice/5h_prac/TFODCourse/tfod_new/env/lib/python3.8/site-packages/urllib3/connectionpool.py", line 386, in _make_request
    self._validate_conn(conn)
  File "/Users/rudra_sarkar/Documents/CNN_practice/5h_prac/TFODCourse/tfod_new/env/lib/python3.8/site-packages/urllib3/connectionpool.py", line 1042, in _validate_conn
    conn.connect()
  File "/Users/rudra_sarkar/Documents/CNN_practice/5h_prac/TFODCourse/tfod_new/env/lib/python3.8/site-packages/urllib3/connection.py", line 358, in connect
    self.sock = conn = self._new_conn()
  File "/Users/rudra_sarkar/Documents/CNN_practice/5h_prac/TFODCourse/tfod_new/env/lib/python3.8/site-packages/urllib3/connection.py", line 186, in _new_conn
    raise NewConnectionError(
urllib3.exceptions.NewConnectionError: <urllib3.connection.HTTPSConnection object at 0x157e977f0>: Failed to establish a new connection: [Errno 8] nodename nor servname provided, or not known

During handling of the above exception, another exception occurred:

Traceback (most recent call last):
  File "/Users/rudra_sarkar/Documents/CNN_practice/5h_prac/TFODCourse/tfod_new/env/lib/python3.8/site-packages/requests/adapters.py", line 489, in send
    resp = conn.urlopen(
  File "/Users/rudra_sarkar/Documents/CNN_practice/5h_prac/TFODCourse/tfod_new/env/lib/python3.8/site-packages/urllib3/connectionpool.py", line 787, in urlopen
    retries = retries.increment(
  File "/Users/rudra_sarkar/Documents/CNN_practice/5h_prac/TFODCourse/tfod_new/env/lib/python3.8/site-packages/urllib3/util/retry.py", line 592, in increment
    raise MaxRetryError(_pool, url, error or ResponseError(cause))
urllib3.exceptions.MaxRetryError: HTTPSConnectionPool(host='api.wandb.ai', port=443): Max retries exceeded with url: /graphql (Caused by NewConnectionError('<urllib3.connection.HTTPSConnection object at 0x157e977f0>: Failed to establish a new connection: [Errno 8] nodename nor servname provided, or not known'))

During handling of the above exception, another exception occurred:

Traceback (most recent call last):
  File "/Users/rudra_sarkar/Documents/CNN_practice/5h_prac/TFODCourse/tfod_new/env/lib/python3.8/site-packages/wandb/sdk/lib/retry.py", line 134, in __call__
    result = self._call_fn(*args, **kwargs)
  File "/Users/rudra_sarkar/Documents/CNN_practice/5h_prac/TFODCourse/tfod_new/env/lib/python3.8/site-packages/wandb/apis/public/api.py", line 79, in execute
    return self._client.execute(*args, **kwargs)
  File "/Users/rudra_sarkar/Documents/CNN_practice/5h_prac/TFODCourse/tfod_new/env/lib/python3.8/site-packages/wandb/vendor/gql-0.2.0/wandb_gql/client.py", line 52, in execute
    result = self._get_result(document, *args, **kwargs)
  File "/Users/rudra_sarkar/Documents/CNN_practice/5h_prac/TFODCourse/tfod_new/env/lib/python3.8/site-packages/wandb/vendor/gql-0.2.0/wandb_gql/client.py", line 60, in _get_result
    return self.transport.execute(document, *args, **kwargs)
  File "/Users/rudra_sarkar/Documents/CNN_practice/5h_prac/TFODCourse/tfod_new/env/lib/python3.8/site-packages/wandb/sdk/lib/gql_request.py", line 58, in execute
    request = self.session.post(self.url, **post_args)
  File "/Users/rudra_sarkar/Documents/CNN_practice/5h_prac/TFODCourse/tfod_new/env/lib/python3.8/site-packages/requests/sessions.py", line 635, in post
    return self.request("POST", url, data=data, json=json, **kwargs)
  File "/Users/rudra_sarkar/Documents/CNN_practice/5h_prac/TFODCourse/tfod_new/env/lib/python3.8/site-packages/requests/sessions.py", line 587, in request
    resp = self.send(prep, **send_kwargs)
  File "/Users/rudra_sarkar/Documents/CNN_practice/5h_prac/TFODCourse/tfod_new/env/lib/python3.8/site-packages/requests/sessions.py", line 701, in send
    r = adapter.send(request, **kwargs)
  File "/Users/rudra_sarkar/Documents/CNN_practice/5h_prac/TFODCourse/tfod_new/env/lib/python3.8/site-packages/requests/adapters.py", line 565, in send
    raise ConnectionError(e, request=request)
requests.exceptions.ConnectionError: HTTPSConnectionPool(host='api.wandb.ai', port=443): Max retries exceeded with url: /graphql (Caused by NewConnectionError('<urllib3.connection.HTTPSConnection object at 0x157e977f0>: Failed to establish a new connection: [Errno 8] nodename nor servname provided, or not known'))
2025-03-15 16:04:53,986 INFO    Thread-16 :21771 [retry.py:__call__():175] Retry attempt failed:
Traceback (most recent call last):
  File "/Users/rudra_sarkar/Documents/CNN_practice/5h_prac/TFODCourse/tfod_new/env/lib/python3.8/site-packages/urllib3/connection.py", line 174, in _new_conn
    conn = connection.create_connection(
  File "/Users/rudra_sarkar/Documents/CNN_practice/5h_prac/TFODCourse/tfod_new/env/lib/python3.8/site-packages/urllib3/util/connection.py", line 72, in create_connection
    for res in socket.getaddrinfo(host, port, family, socket.SOCK_STREAM):
  File "/Users/rudra_sarkar/Documents/CNN_practice/5h_prac/TFODCourse/tfod_new/env/lib/python3.8/socket.py", line 918, in getaddrinfo
    for res in _socket.getaddrinfo(host, port, family, type, proto, flags):
socket.gaierror: [Errno 8] nodename nor servname provided, or not known

During handling of the above exception, another exception occurred:

Traceback (most recent call last):
  File "/Users/rudra_sarkar/Documents/CNN_practice/5h_prac/TFODCourse/tfod_new/env/lib/python3.8/site-packages/urllib3/connectionpool.py", line 703, in urlopen
    httplib_response = self._make_request(
  File "/Users/rudra_sarkar/Documents/CNN_practice/5h_prac/TFODCourse/tfod_new/env/lib/python3.8/site-packages/urllib3/connectionpool.py", line 386, in _make_request
    self._validate_conn(conn)
  File "/Users/rudra_sarkar/Documents/CNN_practice/5h_prac/TFODCourse/tfod_new/env/lib/python3.8/site-packages/urllib3/connectionpool.py", line 1042, in _validate_conn
    conn.connect()
  File "/Users/rudra_sarkar/Documents/CNN_practice/5h_prac/TFODCourse/tfod_new/env/lib/python3.8/site-packages/urllib3/connection.py", line 358, in connect
    self.sock = conn = self._new_conn()
  File "/Users/rudra_sarkar/Documents/CNN_practice/5h_prac/TFODCourse/tfod_new/env/lib/python3.8/site-packages/urllib3/connection.py", line 186, in _new_conn
    raise NewConnectionError(
urllib3.exceptions.NewConnectionError: <urllib3.connection.HTTPSConnection object at 0x17105cfa0>: Failed to establish a new connection: [Errno 8] nodename nor servname provided, or not known

During handling of the above exception, another exception occurred:

Traceback (most recent call last):
  File "/Users/rudra_sarkar/Documents/CNN_practice/5h_prac/TFODCourse/tfod_new/env/lib/python3.8/site-packages/requests/adapters.py", line 489, in send
    resp = conn.urlopen(
  File "/Users/rudra_sarkar/Documents/CNN_practice/5h_prac/TFODCourse/tfod_new/env/lib/python3.8/site-packages/urllib3/connectionpool.py", line 787, in urlopen
    retries = retries.increment(
  File "/Users/rudra_sarkar/Documents/CNN_practice/5h_prac/TFODCourse/tfod_new/env/lib/python3.8/site-packages/urllib3/util/retry.py", line 592, in increment
    raise MaxRetryError(_pool, url, error or ResponseError(cause))
urllib3.exceptions.MaxRetryError: HTTPSConnectionPool(host='api.wandb.ai', port=443): Max retries exceeded with url: /graphql (Caused by NewConnectionError('<urllib3.connection.HTTPSConnection object at 0x17105cfa0>: Failed to establish a new connection: [Errno 8] nodename nor servname provided, or not known'))

During handling of the above exception, another exception occurred:

Traceback (most recent call last):
  File "/Users/rudra_sarkar/Documents/CNN_practice/5h_prac/TFODCourse/tfod_new/env/lib/python3.8/site-packages/wandb/sdk/lib/retry.py", line 134, in __call__
    result = self._call_fn(*args, **kwargs)
  File "/Users/rudra_sarkar/Documents/CNN_practice/5h_prac/TFODCourse/tfod_new/env/lib/python3.8/site-packages/wandb/apis/public/api.py", line 79, in execute
    return self._client.execute(*args, **kwargs)
  File "/Users/rudra_sarkar/Documents/CNN_practice/5h_prac/TFODCourse/tfod_new/env/lib/python3.8/site-packages/wandb/vendor/gql-0.2.0/wandb_gql/client.py", line 52, in execute
    result = self._get_result(document, *args, **kwargs)
  File "/Users/rudra_sarkar/Documents/CNN_practice/5h_prac/TFODCourse/tfod_new/env/lib/python3.8/site-packages/wandb/vendor/gql-0.2.0/wandb_gql/client.py", line 60, in _get_result
    return self.transport.execute(document, *args, **kwargs)
  File "/Users/rudra_sarkar/Documents/CNN_practice/5h_prac/TFODCourse/tfod_new/env/lib/python3.8/site-packages/wandb/sdk/lib/gql_request.py", line 58, in execute
    request = self.session.post(self.url, **post_args)
  File "/Users/rudra_sarkar/Documents/CNN_practice/5h_prac/TFODCourse/tfod_new/env/lib/python3.8/site-packages/requests/sessions.py", line 635, in post
    return self.request("POST", url, data=data, json=json, **kwargs)
  File "/Users/rudra_sarkar/Documents/CNN_practice/5h_prac/TFODCourse/tfod_new/env/lib/python3.8/site-packages/requests/sessions.py", line 587, in request
    resp = self.send(prep, **send_kwargs)
  File "/Users/rudra_sarkar/Documents/CNN_practice/5h_prac/TFODCourse/tfod_new/env/lib/python3.8/site-packages/requests/sessions.py", line 701, in send
    r = adapter.send(request, **kwargs)
  File "/Users/rudra_sarkar/Documents/CNN_practice/5h_prac/TFODCourse/tfod_new/env/lib/python3.8/site-packages/requests/adapters.py", line 565, in send
    raise ConnectionError(e, request=request)
requests.exceptions.ConnectionError: HTTPSConnectionPool(host='api.wandb.ai', port=443): Max retries exceeded with url: /graphql (Caused by NewConnectionError('<urllib3.connection.HTTPSConnection object at 0x17105cfa0>: Failed to establish a new connection: [Errno 8] nodename nor servname provided, or not known'))
2025-03-15 16:05:34,576 INFO    Thread-16 :21771 [wandb_run.py:_config_callback():1261] config_cb ('_wandb', 'visualize', 'Confusion matrix') {'panel_type': 'Vega2', 'panel_config': {'panelDefId': 'wandb/confusion_matrix/v1', 'fieldSettings': {'Actual': 'Actual', 'Predicted': 'Predicted', 'nPredictions': 'nPredictions'}, 'stringSettings': {'title': 'Confusion Matrix Curve'}, 'transform': {'name': 'tableWithLeafColNames'}, 'userQuery': {'queryFields': [{'name': 'runSets', 'args': [{'name': 'runSets', 'value': '${runSets}'}], 'fields': [{'name': 'id', 'fields': []}, {'name': 'name', 'fields': []}, {'name': '_defaultColorIndex', 'fields': []}, {'name': 'summaryTable', 'args': [{'name': 'tableKey', 'value': 'Confusion matrix_table'}], 'fields': []}]}]}}} None
2025-03-15 16:05:37,836 INFO    Thread-16 :21771 [retry.py:__call__():175] Retry attempt failed:
Traceback (most recent call last):
  File "/Users/rudra_sarkar/Documents/CNN_practice/5h_prac/TFODCourse/tfod_new/env/lib/python3.8/site-packages/urllib3/connection.py", line 174, in _new_conn
    conn = connection.create_connection(
  File "/Users/rudra_sarkar/Documents/CNN_practice/5h_prac/TFODCourse/tfod_new/env/lib/python3.8/site-packages/urllib3/util/connection.py", line 72, in create_connection
    for res in socket.getaddrinfo(host, port, family, socket.SOCK_STREAM):
  File "/Users/rudra_sarkar/Documents/CNN_practice/5h_prac/TFODCourse/tfod_new/env/lib/python3.8/socket.py", line 918, in getaddrinfo
    for res in _socket.getaddrinfo(host, port, family, type, proto, flags):
socket.gaierror: [Errno 8] nodename nor servname provided, or not known

During handling of the above exception, another exception occurred:

Traceback (most recent call last):
  File "/Users/rudra_sarkar/Documents/CNN_practice/5h_prac/TFODCourse/tfod_new/env/lib/python3.8/site-packages/urllib3/connectionpool.py", line 703, in urlopen
    httplib_response = self._make_request(
  File "/Users/rudra_sarkar/Documents/CNN_practice/5h_prac/TFODCourse/tfod_new/env/lib/python3.8/site-packages/urllib3/connectionpool.py", line 386, in _make_request
    self._validate_conn(conn)
  File "/Users/rudra_sarkar/Documents/CNN_practice/5h_prac/TFODCourse/tfod_new/env/lib/python3.8/site-packages/urllib3/connectionpool.py", line 1042, in _validate_conn
    conn.connect()
  File "/Users/rudra_sarkar/Documents/CNN_practice/5h_prac/TFODCourse/tfod_new/env/lib/python3.8/site-packages/urllib3/connection.py", line 358, in connect
    self.sock = conn = self._new_conn()
  File "/Users/rudra_sarkar/Documents/CNN_practice/5h_prac/TFODCourse/tfod_new/env/lib/python3.8/site-packages/urllib3/connection.py", line 186, in _new_conn
    raise NewConnectionError(
urllib3.exceptions.NewConnectionError: <urllib3.connection.HTTPSConnection object at 0x156c06730>: Failed to establish a new connection: [Errno 8] nodename nor servname provided, or not known

During handling of the above exception, another exception occurred:

Traceback (most recent call last):
  File "/Users/rudra_sarkar/Documents/CNN_practice/5h_prac/TFODCourse/tfod_new/env/lib/python3.8/site-packages/requests/adapters.py", line 489, in send
    resp = conn.urlopen(
  File "/Users/rudra_sarkar/Documents/CNN_practice/5h_prac/TFODCourse/tfod_new/env/lib/python3.8/site-packages/urllib3/connectionpool.py", line 787, in urlopen
    retries = retries.increment(
  File "/Users/rudra_sarkar/Documents/CNN_practice/5h_prac/TFODCourse/tfod_new/env/lib/python3.8/site-packages/urllib3/util/retry.py", line 592, in increment
    raise MaxRetryError(_pool, url, error or ResponseError(cause))
urllib3.exceptions.MaxRetryError: HTTPSConnectionPool(host='api.wandb.ai', port=443): Max retries exceeded with url: /graphql (Caused by NewConnectionError('<urllib3.connection.HTTPSConnection object at 0x156c06730>: Failed to establish a new connection: [Errno 8] nodename nor servname provided, or not known'))

During handling of the above exception, another exception occurred:

Traceback (most recent call last):
  File "/Users/rudra_sarkar/Documents/CNN_practice/5h_prac/TFODCourse/tfod_new/env/lib/python3.8/site-packages/wandb/sdk/lib/retry.py", line 134, in __call__
    result = self._call_fn(*args, **kwargs)
  File "/Users/rudra_sarkar/Documents/CNN_practice/5h_prac/TFODCourse/tfod_new/env/lib/python3.8/site-packages/wandb/apis/public/api.py", line 79, in execute
    return self._client.execute(*args, **kwargs)
  File "/Users/rudra_sarkar/Documents/CNN_practice/5h_prac/TFODCourse/tfod_new/env/lib/python3.8/site-packages/wandb/vendor/gql-0.2.0/wandb_gql/client.py", line 52, in execute
    result = self._get_result(document, *args, **kwargs)
  File "/Users/rudra_sarkar/Documents/CNN_practice/5h_prac/TFODCourse/tfod_new/env/lib/python3.8/site-packages/wandb/vendor/gql-0.2.0/wandb_gql/client.py", line 60, in _get_result
    return self.transport.execute(document, *args, **kwargs)
  File "/Users/rudra_sarkar/Documents/CNN_practice/5h_prac/TFODCourse/tfod_new/env/lib/python3.8/site-packages/wandb/sdk/lib/gql_request.py", line 58, in execute
    request = self.session.post(self.url, **post_args)
  File "/Users/rudra_sarkar/Documents/CNN_practice/5h_prac/TFODCourse/tfod_new/env/lib/python3.8/site-packages/requests/sessions.py", line 635, in post
    return self.request("POST", url, data=data, json=json, **kwargs)
  File "/Users/rudra_sarkar/Documents/CNN_practice/5h_prac/TFODCourse/tfod_new/env/lib/python3.8/site-packages/requests/sessions.py", line 587, in request
    resp = self.send(prep, **send_kwargs)
  File "/Users/rudra_sarkar/Documents/CNN_practice/5h_prac/TFODCourse/tfod_new/env/lib/python3.8/site-packages/requests/sessions.py", line 701, in send
    r = adapter.send(request, **kwargs)
  File "/Users/rudra_sarkar/Documents/CNN_practice/5h_prac/TFODCourse/tfod_new/env/lib/python3.8/site-packages/requests/adapters.py", line 565, in send
    raise ConnectionError(e, request=request)
requests.exceptions.ConnectionError: HTTPSConnectionPool(host='api.wandb.ai', port=443): Max retries exceeded with url: /graphql (Caused by NewConnectionError('<urllib3.connection.HTTPSConnection object at 0x156c06730>: Failed to establish a new connection: [Errno 8] nodename nor servname provided, or not known'))
2025-03-15 16:11:26,718 INFO    Thread-16 :21771 [wandb_run.py:_config_callback():1261] config_cb ('_wandb', 'visualize', 'Confusion matrix') {'panel_type': 'Vega2', 'panel_config': {'panelDefId': 'wandb/confusion_matrix/v1', 'fieldSettings': {'Actual': 'Actual', 'Predicted': 'Predicted', 'nPredictions': 'nPredictions'}, 'stringSettings': {'title': 'Confusion Matrix Curve'}, 'transform': {'name': 'tableWithLeafColNames'}, 'userQuery': {'queryFields': [{'name': 'runSets', 'args': [{'name': 'runSets', 'value': '${runSets}'}], 'fields': [{'name': 'id', 'fields': []}, {'name': 'name', 'fields': []}, {'name': '_defaultColorIndex', 'fields': []}, {'name': 'summaryTable', 'args': [{'name': 'tableKey', 'value': 'Confusion matrix_table'}], 'fields': []}]}]}}} None
2025-03-15 16:11:40,237 INFO    Thread-16 :21771 [wandb_run.py:_config_callback():1261] config_cb ('_wandb', 'visualize', 'Confusion matrix') {'panel_type': 'Vega2', 'panel_config': {'panelDefId': 'wandb/confusion_matrix/v1', 'fieldSettings': {'Actual': 'Actual', 'Predicted': 'Predicted', 'nPredictions': 'nPredictions'}, 'stringSettings': {'title': 'Confusion Matrix Curve'}, 'transform': {'name': 'tableWithLeafColNames'}, 'userQuery': {'queryFields': [{'name': 'runSets', 'args': [{'name': 'runSets', 'value': '${runSets}'}], 'fields': [{'name': 'id', 'fields': []}, {'name': 'name', 'fields': []}, {'name': '_defaultColorIndex', 'fields': []}, {'name': 'summaryTable', 'args': [{'name': 'tableKey', 'value': 'Confusion matrix_table'}], 'fields': []}]}]}}} None
2025-03-15 16:11:50,714 INFO    Thread-16 :21771 [wandb_run.py:_config_callback():1261] config_cb ('_wandb', 'visualize', 'Confusion matrix') {'panel_type': 'Vega2', 'panel_config': {'panelDefId': 'wandb/confusion_matrix/v1', 'fieldSettings': {'Actual': 'Actual', 'Predicted': 'Predicted', 'nPredictions': 'nPredictions'}, 'stringSettings': {'title': 'Confusion Matrix Curve'}, 'transform': {'name': 'tableWithLeafColNames'}, 'userQuery': {'queryFields': [{'name': 'runSets', 'args': [{'name': 'runSets', 'value': '${runSets}'}], 'fields': [{'name': 'id', 'fields': []}, {'name': 'name', 'fields': []}, {'name': '_defaultColorIndex', 'fields': []}, {'name': 'summaryTable', 'args': [{'name': 'tableKey', 'value': 'Confusion matrix_table'}], 'fields': []}]}]}}} None
2025-03-15 16:12:00,796 INFO    Thread-16 :21771 [wandb_run.py:_config_callback():1261] config_cb ('_wandb', 'visualize', 'Confusion matrix') {'panel_type': 'Vega2', 'panel_config': {'panelDefId': 'wandb/confusion_matrix/v1', 'fieldSettings': {'Actual': 'Actual', 'Predicted': 'Predicted', 'nPredictions': 'nPredictions'}, 'stringSettings': {'title': 'Confusion Matrix Curve'}, 'transform': {'name': 'tableWithLeafColNames'}, 'userQuery': {'queryFields': [{'name': 'runSets', 'args': [{'name': 'runSets', 'value': '${runSets}'}], 'fields': [{'name': 'id', 'fields': []}, {'name': 'name', 'fields': []}, {'name': '_defaultColorIndex', 'fields': []}, {'name': 'summaryTable', 'args': [{'name': 'tableKey', 'value': 'Confusion matrix_table'}], 'fields': []}]}]}}} None
2025-03-15 16:12:07,302 INFO    Thread-16 :21771 [wandb_run.py:_finish():2112] finishing run da24d008-iit-madras/da24d008-assignment1/xf9las1e
2025-03-15 16:12:07,302 INFO    Thread-16 :21771 [wandb_run.py:_atexit_cleanup():2340] got exitcode: 0
2025-03-15 16:12:07,302 INFO    Thread-16 :21771 [wandb_run.py:_restore():2322] restore
2025-03-15 16:12:07,302 INFO    Thread-16 :21771 [wandb_run.py:_restore():2328] restore done
2025-03-15 16:12:52,204 INFO    Thread-16 :21771 [wandb_run.py:_footer_history_summary_info():3956] rendering history
2025-03-15 16:12:52,206 INFO    Thread-16 :21771 [wandb_run.py:_footer_history_summary_info():3988] rendering summary
2025-03-15 16:12:52,207 INFO    Thread-16 :21771 [wandb_run.py:_footer_sync_info():3917] logging synced files
